<?xml version="1.0" ?>
<robot name="final_leg">

<material name="silver">
  <color rgba="0.700 0.700 0.700 1.000"/>
</material>

<link name="base_link">
  <inertial>
    <origin xyz="0.029165067835582703 0.017099999999943098 0.14920069924998403" rpy="0 0 0"/>
    <mass value="0.04604548230153534"/>
    <inertia ixx="8.016869330744122e-06" iyy="1.2595635604748965e-05" izz="7.687906298049123e-06" ixy="-3.7377869896437765e-17" iyz="2.5059435863200585e-15" ixz="2.7015096600637454e-08"/>
  </inertial>
  <visual>
    <origin xyz="0 0 0" rpy="0 0 0"/>
    <geometry>
      <mesh filename="meshes/base_link.stl" scale="0.001 0.001 0.001"/>
    </geometry>
    <material name="silver"/>
    <material/>
  </visual>
  <collision>
    <origin xyz="0 0 0" rpy="0 0 0"/>
    <geometry>
      <mesh filename="meshes/base_link.stl" scale="0.001 0.001 0.001"/>
    </geometry>
  </collision>
</link>

<link name="shoulder_servo_arm1">
  <inertial>
    <origin xyz="-0.13968235309937027 0.01708522170302473 -0.04286264911256449" rpy="0 0 0"/>
    <mass value="0.0032701003729527518"/>
    <inertia ixx="3.543164263377453e-07" iyy="3.264260121132914e-07" izz="4.503532556810385e-08" ixy="-3.977552318850492e-11" iyz="4.0594452025059335e-09" ixz="-2.5082431811573912e-09"/>
  </inertial>
  <visual>
    <origin xyz="-0.1941 0.0 -0.1901" rpy="0 0 0"/>
    <geometry>
      <mesh filename="meshes/shoulder_servo_arm1.stl" scale="0.001 0.001 0.001"/>
    </geometry>
    <material name="silver"/>
    <material/>
  </visual>
  <collision>
    <origin xyz="-0.1941 0.0 -0.1901" rpy="0 0 0"/>
    <geometry>
      <mesh filename="meshes/shoulder_servo_arm1.stl" scale="0.001 0.001 0.001"/>
    </geometry>
  </collision>
</link>

<link name="leg_hip_servo_holder_v5_11">
  <inertial>
    <origin xyz="0.029062116445360706 0.0007341121907182037 0.015154097258800042" rpy="0 0 0"/>
    <mass value="0.033229792118666564"/>
    <inertia ixx="9.816230617152818e-06" iyy="2.737918498176787e-05" izz="2.235196763855315e-05" ixy="-9.316882859989098e-08" iyz="1.7284014712554586e-07" ixz="-1.9005758203140028e-06"/>
  </inertial>
  <visual>
    <origin xyz="-0.056835 -0.0171 -0.139365" rpy="0 0 0"/>
    <geometry>
      <mesh filename="meshes/leg_hip_servo_holder_v5_11.stl" scale="0.001 0.001 0.001"/>
    </geometry>
    <material name="silver"/>
    <material/>
  </visual>
  <collision>
    <origin xyz="-0.056835 -0.0171 -0.139365" rpy="0 0 0"/>
    <geometry>
      <mesh filename="meshes/leg_hip_servo_holder_v5_11.stl" scale="0.001 0.001 0.001"/>
    </geometry>
  </collision>
</link>

<link name="femur_servo1">
  <inertial>
    <origin xyz="0.023427805364087104 -0.029329939426677342 -0.00578532392517675" rpy="0 0 0"/>
    <mass value="0.04604548230153534"/>
    <inertia ixx="7.68790629804934e-06" iyy="8.016869330743472e-06" izz="1.2595635604748748e-05" ixy="-2.7015096600705216e-08" iyz="-3.735076484212563e-17" ixz="-2.506024901482995e-15"/>
  </inertial>
  <visual>
    <origin xyz="-0.066416 -0.0495 -0.164071" rpy="0 0 0"/>
    <geometry>
      <mesh filename="meshes/femur_servo1.stl" scale="0.001 0.001 0.001"/>
    </geometry>
    <material name="silver"/>
    <material/>
  </visual>
  <collision>
    <origin xyz="-0.066416 -0.0495 -0.164071" rpy="0 0 0"/>
    <geometry>
      <mesh filename="meshes/femur_servo1.stl" scale="0.001 0.001 0.001"/>
    </geometry>
  </collision>
</link>

<link name="tibia_servo1">
  <inertial>
    <origin xyz="0.02375645324186261 -0.029329939426677307 -0.005785323925346586" rpy="0 0 0"/>
    <mass value="0.04604548230153534"/>
    <inertia ixx="7.687906298049015e-06" iyy="8.016869330743689e-06" izz="1.2595635604748803e-05" ixy="2.7015096600705216e-08" iyz="3.7377869896437765e-17" ixz="-2.5059164812657464e-15"/>
  </inertial>
  <visual>
    <origin xyz="-0.066416 -0.0495 -0.143571" rpy="0 0 0"/>
    <geometry>
      <mesh filename="meshes/tibia_servo1.stl" scale="0.001 0.001 0.001"/>
    </geometry>
    <material name="silver"/>
    <material/>
  </visual>
  <collision>
    <origin xyz="-0.066416 -0.0495 -0.143571" rpy="0 0 0"/>
    <geometry>
      <mesh filename="meshes/tibia_servo1.stl" scale="0.001 0.001 0.001"/>
    </geometry>
  </collision>
</link>

<link name="femur_servo_arm1">
  <inertial>
    <origin xyz="-0.08588986601718922 0.15860348150751336 -0.0038325216322676603" rpy="0 0 0"/>
    <mass value="0.0032701003729527518"/>
    <inertia ixx="1.7284050613712663e-07" iyy="3.5431642633773175e-07" izz="1.9862083152799202e-07" ixy="-1.9035960869916124e-09" iyz="-1.63376491186124e-09" ixz="-1.401624144327959e-07"/>
  </inertial>
  <visual>
    <origin xyz="-0.160016 0.163686 -0.156886" rpy="0 0 0"/>
    <geometry>
      <mesh filename="meshes/femur_servo_arm1.stl" scale="0.001 0.001 0.001"/>
    </geometry>
    <material name="silver"/>
    <material/>
  </visual>
  <collision>
    <origin xyz="-0.160016 0.163686 -0.156886" rpy="0 0 0"/>
    <geometry>
      <mesh filename="meshes/femur_servo_arm1.stl" scale="0.001 0.001 0.001"/>
    </geometry>
  </collision>
</link>

<link name="tibia_servo_arm1">
  <inertial>
    <origin xyz="0.10590207917078587 0.13810348150751334 -0.006619051427954548" rpy="0 0 0"/>
    <mass value="0.0032701003729527518"/>
    <inertia ixx="1.6518892893783847e-07" iyy="3.5431642633773175e-07" izz="2.0627240872726662e-07" ixy="1.8483500907451577e-09" iyz="-1.6960152687050747e-09" ixz="1.3924688734778476e-07"/>
  </inertial>
  <visual>
    <origin xyz="-0.0 0.143186 -0.139186" rpy="0 0 0"/>
    <geometry>
      <mesh filename="meshes/tibia_servo_arm1.stl" scale="0.001 0.001 0.001"/>
    </geometry>
    <material name="silver"/>
    <material/>
  </visual>
  <collision>
    <origin xyz="-0.0 0.143186 -0.139186" rpy="0 0 0"/>
    <geometry>
      <mesh filename="meshes/tibia_servo_arm1.stl" scale="0.001 0.001 0.001"/>
    </geometry>
  </collision>
</link>

<link name="leg_knee_connector1">
  <inertial>
    <origin xyz="0.009052148550595808 -0.007651583401671309 -0.009315363602751564" rpy="0 0 0"/>
    <mass value="0.003678869307692891"/>
    <inertia ixx="2.796723810536821e-07" iyy="4.694247983760933e-07" izz="2.692538170776261e-07" ixy="3.405201411305859e-08" iyz="-3.5029641426251475e-08" ixz="1.8269052767929333e-07"/>
  </inertial>
  <visual>
    <origin xyz="-0.062046 0.0077 -0.142368" rpy="0 0 0"/>
    <geometry>
      <mesh filename="meshes/leg_knee_connector1.stl" scale="0.001 0.001 0.001"/>
    </geometry>
    <material name="silver"/>
    <material/>
  </visual>
  <collision>
    <origin xyz="-0.062046 0.0077 -0.142368" rpy="0 0 0"/>
    <geometry>
      <mesh filename="meshes/leg_knee_connector1.stl" scale="0.001 0.001 0.001"/>
    </geometry>
  </collision>
</link>

<link name="leg_knee_up1">
  <inertial>
    <origin xyz="-0.036503310672611367 -0.008220871500145008 -0.029417409206797737" rpy="0 0 0"/>
    <mass value="0.01576780550429841"/>
    <inertia ixx="6.128582418553428e-06" iyy="1.4262775173222127e-05" izz="9.097534993084784e-06" ixy="2.2284640665603528e-07" iyz="1.8446721232763717e-07" ixz="-6.700750409080388e-06"/>
  </inertial>
  <visual>
    <origin xyz="-0.100008 0.0077 -0.137786" rpy="0 0 0"/>
    <geometry>
      <mesh filename="meshes/leg_knee_up1.stl" scale="0.001 0.001 0.001"/>
    </geometry>
    <material name="silver"/>
    <material/>
  </visual>
  <collision>
    <origin xyz="-0.100008 0.0077 -0.137786" rpy="0 0 0"/>
    <geometry>
      <mesh filename="meshes/leg_knee_up1.stl" scale="0.001 0.001 0.001"/>
    </geometry>
  </collision>
</link>

<link name="leg_knee_connector1">
  <inertial>
    <origin xyz="-0.009232851449404195 -0.0030015834016713094 -0.015439363602751582" rpy="0 0 0"/>
    <mass value="0.003678869307692891"/>
    <inertia ixx="2.796723810536821e-07" iyy="4.694247983760933e-07" izz="2.692538170776261e-07" ixy="3.405201411305859e-08" iyz="-3.5029641426251475e-08" ixz="1.8269052767929333e-07"/>
  </inertial>
  <visual>
    <origin xyz="-0.080331 0.01235 -0.148492" rpy="0 0 0"/>
    <geometry>
      <mesh filename="meshes/leg_knee_connector1.stl" scale="0.001 0.001 0.001"/>
    </geometry>
    <material name="silver"/>
    <material/>
  </visual>
  <collision>
    <origin xyz="-0.080331 0.01235 -0.148492" rpy="0 0 0"/>
    <geometry>
      <mesh filename="meshes/leg_knee_connector1.stl" scale="0.001 0.001 0.001"/>
    </geometry>
  </collision>
</link>

<link name="leg_knee_down1">
  <inertial>
    <origin xyz="-0.032578154068042126 -0.03195635497968314 -0.03207308749751338" rpy="0 0 0"/>
    <mass value="0.12529857948474465"/>
    <inertia ixx="5.4540249712071174e-05" iyy="0.00010639788511163767" izz="7.642478538915612e-05" ixy="-1.996080888490119e-08" iyz="2.8443939014842403e-08" ixz="-5.027696896980059e-05"/>
  </inertial>
  <visual>
    <origin xyz="-0.117947 0.0077 -0.121842" rpy="0 0 0"/>
    <geometry>
      <mesh filename="meshes/leg_knee_down1.stl" scale="0.001 0.001 0.001"/>
    </geometry>
    <material name="silver"/>
    <material/>
  </visual>
  <collision>
    <origin xyz="-0.117947 0.0077 -0.121842" rpy="0 0 0"/>
    <geometry>
      <mesh filename="meshes/leg_knee_down1.stl" scale="0.001 0.001 0.001"/>
    </geometry>
  </collision>
</link>

<link name="leg_ankle1">
  <inertial>
    <origin xyz="0.03611001312152397 -0.0066003308381630335 -0.031037405254005036" rpy="0 0 0"/>
    <mass value="0.02126702507166657"/>
    <inertia ixx="8.503357412330881e-06" iyy="1.73719748683417e-05" izz="1.1850694528502042e-05" ixy="6.801970161299459e-11" iyz="-2.0862937550948136e-10" ixz="8.142627489893126e-06"/>
  </inertial>
  <visual>
    <origin xyz="-0.031405 0.0077 -0.078641" rpy="0 0 0"/>
    <geometry>
      <mesh filename="meshes/leg_ankle1.stl" scale="0.001 0.001 0.001"/>
    </geometry>
    <material name="silver"/>
    <material/>
  </visual>
  <collision>
    <origin xyz="-0.031405 0.0077 -0.078641" rpy="0 0 0"/>
    <geometry>
      <mesh filename="meshes/leg_ankle1.stl" scale="0.001 0.001 0.001"/>
    </geometry>
  </collision>
</link>

<link name="leg_ankle1">
  <inertial>
    <origin xyz="0.018172013121523972 -0.0066003308381630335 -0.015010405254005037" rpy="0 0 0"/>
    <mass value="0.02126702507166657"/>
    <inertia ixx="8.503357412330881e-06" iyy="1.73719748683417e-05" izz="1.1850694528502042e-05" ixy="6.801970161299459e-11" iyz="-2.0862937550948136e-10" ixz="8.142627489893126e-06"/>
  </inertial>
  <visual>
    <origin xyz="-0.049343 0.0077 -0.062614" rpy="0 0 0"/>
    <geometry>
      <mesh filename="meshes/leg_ankle1.stl" scale="0.001 0.001 0.001"/>
    </geometry>
    <material name="silver"/>
    <material/>
  </visual>
  <collision>
    <origin xyz="-0.049343 0.0077 -0.062614" rpy="0 0 0"/>
    <geometry>
      <mesh filename="meshes/leg_ankle1.stl" scale="0.001 0.001 0.001"/>
    </geometry>
  </collision>
</link>

<link name="leg_foot1Component161">
  <inertial>
    <origin xyz="0.0005508898569509674 -5.0905187218303755e-05 0.04461354496870405" rpy="0 0 0"/>
    <mass value="0.27066128094400904"/>
    <inertia ixx="0.00012915790138998086" iyy="0.00012850524910022884" izz="2.1765031159176346e-05" ixy="-1.0060013751493537e-07" iyz="-5.043394982063697e-07" ixz="1.2848982361771122e-06"/>
  </inertial>
  <visual>
    <origin xyz="-0.098856 0.0143 -0.019125" rpy="0 0 0"/>
    <geometry>
      <mesh filename="meshes/leg_foot1Component161.stl" scale="0.001 0.001 0.001"/>
    </geometry>
    <material name="silver"/>
    <material/>
  </visual>
  <collision>
    <origin xyz="-0.098856 0.0143 -0.019125" rpy="0 0 0"/>
    <geometry>
      <mesh filename="meshes/leg_foot1Component161.stl" scale="0.001 0.001 0.001"/>
    </geometry>
  </collision>
</link>

<joint name="Revolute_23" type="continuous">
  <origin xyz="0.1941 0.0 0.1901" rpy="0 0 0"/>
  <parent link="base_link"/>
  <child link="shoulder_servo_arm1"/>
  <axis xyz="-1.0 0.0 0.0"/>
</joint>
<transmission name="Revolute_23_tran">
  <type>transmission_interface/SimpleTransmission</type>
  <joint name="Revolute_23">
    <hardwareInterface>PositionJointInterface</hardwareInterface>
  </joint>
  <actuator name="Revolute_23_actr">
    <hardwareInterface>PositionJointInterface</hardwareInterface>
    <mechanicalReduction>1</mechanicalReduction>
  </actuator>
</transmission>

<joint name="Rigid_24" type="fixed">
  <origin xyz="-0.137265 0.0171 -0.050735" rpy="0 0 0"/>
  <parent link="shoulder_servo_arm1"/>
  <child link="leg_hip_servo_holder_v5_11"/>
</joint>

<joint name="Rigid_25" type="fixed">
  <origin xyz="0.009581 0.0324 0.024706" rpy="0 0 0"/>
  <parent link="leg_hip_servo_holder_v5_11"/>
  <child link="femur_servo1"/>
</joint>

<joint name="Rigid_26" type="fixed">
  <origin xyz="0.009581 0.0324 0.004206" rpy="0 0 0"/>
  <parent link="leg_hip_servo_holder_v5_11"/>
  <child link="tibia_servo1"/>
</joint>

<joint name="Revolute_27" type="continuous">
  <origin xyz="0.0936 -0.213186 -0.007185" rpy="0 0 0"/>
  <parent link="femur_servo1"/>
  <child link="femur_servo_arm1"/>
  <axis xyz="-0.0 1.0 -0.0"/>
</joint>
<transmission name="Revolute_27_tran">
  <type>transmission_interface/SimpleTransmission</type>
  <joint name="Revolute_27">
    <hardwareInterface>PositionJointInterface</hardwareInterface>
  </joint>
  <actuator name="Revolute_27_actr">
    <hardwareInterface>PositionJointInterface</hardwareInterface>
    <mechanicalReduction>1</mechanicalReduction>
  </actuator>
</transmission>

<joint name="Revolute_28" type="continuous">
  <origin xyz="-0.066416 -0.192686 -0.004385" rpy="0 0 0"/>
  <parent link="tibia_servo1"/>
  <child link="tibia_servo_arm1"/>
  <axis xyz="-0.0 1.0 -0.0"/>
</joint>
<transmission name="Revolute_28_tran">
  <type>transmission_interface/SimpleTransmission</type>
  <joint name="Revolute_28">
    <hardwareInterface>PositionJointInterface</hardwareInterface>
  </joint>
  <actuator name="Revolute_28_actr">
    <hardwareInterface>PositionJointInterface</hardwareInterface>
    <mechanicalReduction>1</mechanicalReduction>
  </actuator>
</transmission>

<joint name="Revolute_29" type="continuous">
  <origin xyz="-0.079685 0.151336 -0.008394" rpy="0 0 0"/>
  <parent link="femur_servo_arm1"/>
  <child link="leg_knee_connector1"/>
  <axis xyz="-0.0 -1.0 0.0"/>
</joint>
<transmission name="Revolute_29_tran">
  <type>transmission_interface/SimpleTransmission</type>
  <joint name="Revolute_29">
    <hardwareInterface>PositionJointInterface</hardwareInterface>
  </joint>
  <actuator name="Revolute_29_actr">
    <hardwareInterface>PositionJointInterface</hardwareInterface>
    <mechanicalReduction>1</mechanicalReduction>
  </actuator>
</transmission>

<joint name="Revolute_30" type="continuous">
  <origin xyz="0.100008 0.135486 -0.0014" rpy="0 0 0"/>
  <parent link="tibia_servo_arm1"/>
  <child link="leg_knee_up1"/>
  <axis xyz="-0.0 1.0 -0.0"/>
</joint>
<transmission name="Revolute_30_tran">
  <type>transmission_interface/SimpleTransmission</type>
  <joint name="Revolute_30">
    <hardwareInterface>PositionJointInterface</hardwareInterface>
  </joint>
  <actuator name="Revolute_30_actr">
    <hardwareInterface>PositionJointInterface</hardwareInterface>
    <mechanicalReduction>1</mechanicalReduction>
  </actuator>
</transmission>

<joint name="Cylindrical_31" type="Cylinderical">
  <origin xyz="-0.019677 -0.00465 0.010706" rpy="0 0 0"/>
  <parent link="leg_knee_up1"/>
  <child link="leg_knee_connector1"/>
</joint>
<transmission name="Cylindrical_31_tran">
  <type>transmission_interface/SimpleTransmission</type>
  <joint name="Cylindrical_31">
    <hardwareInterface>PositionJointInterface</hardwareInterface>
  </joint>
  <actuator name="Cylindrical_31_actr">
    <hardwareInterface>PositionJointInterface</hardwareInterface>
    <mechanicalReduction>1</mechanicalReduction>
  </actuator>
</transmission>

<joint name="Revolute_32" type="continuous">
  <origin xyz="0.117947 0.135486 -0.017344" rpy="0 0 0"/>
  <parent link="tibia_servo_arm1"/>
  <child link="leg_knee_down1"/>
  <axis xyz="0.0 -1.0 0.0"/>
</joint>
<transmission name="Revolute_32_tran">
  <type>transmission_interface/SimpleTransmission</type>
  <joint name="Revolute_32">
    <hardwareInterface>PositionJointInterface</hardwareInterface>
  </joint>
  <actuator name="Revolute_32_actr">
    <hardwareInterface>PositionJointInterface</hardwareInterface>
    <mechanicalReduction>1</mechanicalReduction>
  </actuator>
</transmission>

<joint name="Revolute_33" type="continuous">
  <origin xyz="-0.050665 0.0 -0.075172" rpy="0 0 0"/>
  <parent link="leg_knee_up1"/>
  <child link="leg_ankle1"/>
  <axis xyz="-0.0 -1.0 0.0"/>
</joint>
<transmission name="Revolute_33_tran">
  <type>transmission_interface/SimpleTransmission</type>
  <joint name="Revolute_33">
    <hardwareInterface>PositionJointInterface</hardwareInterface>
  </joint>
  <actuator name="Revolute_33_actr">
    <hardwareInterface>PositionJointInterface</hardwareInterface>
    <mechanicalReduction>1</mechanicalReduction>
  </actuator>
</transmission>

<joint name="Revolute_34" type="continuous">
  <origin xyz="-0.068604 0.0 -0.059228" rpy="0 0 0"/>
  <parent link="leg_knee_down1"/>
  <child link="leg_ankle1"/>
  <axis xyz="-0.0 1.0 -0.0"/>
</joint>
<transmission name="Revolute_34_tran">
  <type>transmission_interface/SimpleTransmission</type>
  <joint name="Revolute_34">
    <hardwareInterface>PositionJointInterface</hardwareInterface>
  </joint>
  <actuator name="Revolute_34_actr">
    <hardwareInterface>PositionJointInterface</hardwareInterface>
    <mechanicalReduction>1</mechanicalReduction>
  </actuator>
</transmission>

<joint name="Rigid_35" type="fixed">
  <origin xyz="0.049513 -0.0066 -0.043489" rpy="0 0 0"/>
  <parent link="leg_ankle1"/>
  <child link="leg_foot1Component161"/>
</joint>

</robot>
