<?xml version="1.0" ?>
<robot name="body_urdf">

<material name="silver">
  <color rgba="0.700 0.700 0.700 1.000"/>
</material>

<link name="base_link">
  <inertial>
    <origin xyz="-0.09832294338458615 0.1308688922668954 0.014562295681538818" rpy="0 0 0"/>
    <mass value="1.0091264990609587"/>
    <inertia ixx="0.006444104092593338" iyy="0.0006187182912900362" izz="0.006492899213548932" ixy="3.1017381210396086e-05" iyz="-1.106358624542521e-05" ixz="0.00012583594730295757"/>
  </inertial>
  <visual>
    <origin xyz="0 0 0" rpy="0 0 0"/>
    <geometry>
      <mesh filename="meshes/base_link.stl" scale="0.001 0.001 0.001"/>
    </geometry>
    <material name="silver"/>
    <material/>
  </visual>
  <collision>
    <origin xyz="0 0 0" rpy="0 0 0"/>
    <geometry>
      <mesh filename="meshes/base_link.stl" scale="0.001 0.001 0.001"/>
    </geometry>
  </collision>
</link>

<link name="final_body_right_v11">
  <inertial>
    <origin xyz="0.03084929023590735 0.13578873455716275 0.010080476393786718" rpy="0 0 0"/>
    <mass value="1.0573685832129545"/>
    <inertia ixx="0.006673519250288529" iyy="0.0006716967260792454" izz="0.00676487921131453" ixy="3.0295167626065433e-05" iyz="1.0555750832457605e-05" ixz="-0.0001414940180916987"/>
  </inertial>
  <visual>
    <origin xyz="0.066 0.003 -0.004" rpy="0 0 0"/>
    <geometry>
      <mesh filename="meshes/final_body_right_v11.stl" scale="0.001 0.001 0.001"/>
    </geometry>
    <material name="silver"/>
    <material/>
  </visual>
  <collision>
    <origin xyz="0.066 0.003 -0.004" rpy="0 0 0"/>
    <geometry>
      <mesh filename="meshes/final_body_right_v11.stl" scale="0.001 0.001 0.001"/>
    </geometry>
  </collision>
</link>

<link name="final_body_top_back_v11">
  <inertial>
    <origin xyz="0.03733609341330517 0.0685774653288937 0.0025953340692637245" rpy="0 0 0"/>
    <mass value="0.24941485988842652"/>
    <inertia ixx="0.0004748040246053322" iyy="0.0002446467937671842" izz="0.0007179299991387799" ixy="3.7952674485700316e-06" iyz="2.5539268485221672e-06" ixz="2.0392514878770848e-08"/>
  </inertial>
  <visual>
    <origin xyz="0.1032 0.003 -0.06253" rpy="0 0 0"/>
    <geometry>
      <mesh filename="meshes/final_body_top_back_v11.stl" scale="0.001 0.001 0.001"/>
    </geometry>
    <material name="silver"/>
    <material/>
  </visual>
  <collision>
    <origin xyz="0.1032 0.003 -0.06253" rpy="0 0 0"/>
    <geometry>
      <mesh filename="meshes/final_body_top_back_v11.stl" scale="0.001 0.001 0.001"/>
    </geometry>
  </collision>
</link>

<link name="final_body_top_front_v11">
  <inertial>
    <origin xyz="-0.03743787423794786 -0.08646398439485603 0.0021478138289388188" rpy="0 0 0"/>
    <mass value="0.26735979522124304"/>
    <inertia ixx="0.0005313120601983228" iyy="0.00027561794314928363" izz="0.0008054604598366679" ixy="-4.744508627515208e-07" iyz="2.0182315194081438e-06" ixz="1.0163750948960666e-07"/>
  </inertial>
  <visual>
    <origin xyz="0.0288 -0.267 -0.06253" rpy="0 0 0"/>
    <geometry>
      <mesh filename="meshes/final_body_top_front_v11.stl" scale="0.001 0.001 0.001"/>
    </geometry>
    <material name="silver"/>
    <material/>
  </visual>
  <collision>
    <origin xyz="0.0288 -0.267 -0.06253" rpy="0 0 0"/>
    <geometry>
      <mesh filename="meshes/final_body_top_front_v11.stl" scale="0.001 0.001 0.001"/>
    </geometry>
  </collision>
</link>

<link name="final_body_face_v11">
  <inertial>
    <origin xyz="1.2754717540752747e-06 0.0012835559172246769 0.035539816802552186" rpy="0 0 0"/>
    <mass value="0.1630730098056556"/>
    <inertia ixx="5.5851881092635475e-05" iyy="0.00031552789977539234" izz="0.0002600051256149982" ixy="-7.730017741354456e-10" iyz="-4.0992670012683467e-07" ixz="6.10425678721719e-09"/>
  </inertial>
  <visual>
    <origin xyz="0.066 -0.267 0.0" rpy="0 0 0"/>
    <geometry>
      <mesh filename="meshes/final_body_face_v11.stl" scale="0.001 0.001 0.001"/>
    </geometry>
    <material name="silver"/>
    <material/>
  </visual>
  <collision>
    <origin xyz="0.066 -0.267 0.0" rpy="0 0 0"/>
    <geometry>
      <mesh filename="meshes/final_body_face_v11.stl" scale="0.001 0.001 0.001"/>
    </geometry>
  </collision>
</link>

<link name="final_body_ass_v11">
  <inertial>
    <origin xyz="2.020921643233753e-05 -0.0009999999999999966 0.03448034290306755" rpy="0 0 0"/>
    <mass value="0.14143508899737656"/>
    <inertia ixx="5.2644019507456597e-05" iyy="0.0002627695931459687" izz="0.0002102198636978436" ixy="6.776263578034403e-21" iyz="0.0" ixz="3.7330252715948344e-08"/>
  </inertial>
  <visual>
    <origin xyz="0.066 0.003 -0.0" rpy="0 0 0"/>
    <geometry>
      <mesh filename="meshes/final_body_ass_v11.stl" scale="0.001 0.001 0.001"/>
    </geometry>
    <material name="silver"/>
    <material/>
  </visual>
  <collision>
    <origin xyz="0.066 0.003 -0.0" rpy="0 0 0"/>
    <geometry>
      <mesh filename="meshes/final_body_ass_v11.stl" scale="0.001 0.001 0.001"/>
    </geometry>
  </collision>
</link>

<link name="BL_shoulder_servo_v11">
  <inertial>
    <origin xyz="0.005000000417158992 0.010978373638995828 0.024635264790648363" rpy="0 0 0"/>
    <mass value="0.04601290048863176"/>
    <inertia ixx="1.2574710791247263e-05" iyy="8.00044061970498e-06" izz="7.68339797587803e-06" ixy="4.423544863740858e-17" iyz="-2.7077995843797316e-08" ixz="-3.396751196288461e-15"/>
  </inertial>
  <visual>
    <origin xyz="0.1265 -0.091873 -0.010595" rpy="0 0 0"/>
    <geometry>
      <mesh filename="meshes/BL_shoulder_servo_v11.stl" scale="0.001 0.001 0.001"/>
    </geometry>
    <material name="silver"/>
    <material/>
  </visual>
  <collision>
    <origin xyz="0.1265 -0.091873 -0.010595" rpy="0 0 0"/>
    <geometry>
      <mesh filename="meshes/BL_shoulder_servo_v11.stl" scale="0.001 0.001 0.001"/>
    </geometry>
  </collision>
</link>

<link name="BL_shoulder_servo_arm_v11">
  <inertial>
    <origin xyz="-1.4774175266532574e-05 -0.0031825221993156266 0.007872037110583999" rpy="0 0 0"/>
    <mass value="0.0032700969311456954"/>
    <inertia ixx="3.264258865628831e-07" iyy="3.5431626266497937e-07" izz="4.5035218574967714e-08" ixy="3.9807992656632016e-11" iyz="2.508121760210906e-09" ixz="4.059464669674425e-09"/>
  </inertial>
  <visual>
    <origin xyz="0.1215 -0.081273 -0.025395" rpy="0 0 0"/>
    <geometry>
      <mesh filename="meshes/BL_shoulder_servo_arm_v11.stl" scale="0.001 0.001 0.001"/>
    </geometry>
    <material name="silver"/>
    <material/>
  </visual>
  <collision>
    <origin xyz="0.1215 -0.081273 -0.025395" rpy="0 0 0"/>
    <geometry>
      <mesh filename="meshes/BL_shoulder_servo_arm_v11.stl" scale="0.001 0.001 0.001"/>
    </geometry>
  </collision>
</link>

<link name="BL_leg_hip_servo_holder_v11">
  <inertial>
    <origin xyz="0.0003111372642049248 -0.02973403507055474 0.014853630357813653" rpy="0 0 0"/>
    <mass value="0.035759291462307746"/>
    <inertia ixx="2.9574958845607823e-05" iyy="1.0644821498813828e-05" izz="2.4203084441789375e-05" ixy="3.0545762537523453e-08" iyz="1.8965558623796816e-06" ixz="7.420743759439081e-08"/>
  </inertial>
  <visual>
    <origin xyz="0.1215 -0.075473 -0.025395" rpy="0 0 0"/>
    <geometry>
      <mesh filename="meshes/BL_leg_hip_servo_holder_v11.stl" scale="0.001 0.001 0.001"/>
    </geometry>
    <material name="silver"/>
    <material/>
  </visual>
  <collision>
    <origin xyz="0.1215 -0.075473 -0.025395" rpy="0 0 0"/>
    <geometry>
      <mesh filename="meshes/BL_leg_hip_servo_holder_v11.stl" scale="0.001 0.001 0.001"/>
    </geometry>
  </collision>
</link>

<link name="BL_femur_servo_v11">
  <inertial>
    <origin xyz="0.01097837415844323 0.02463555880899092 0.0050003579729185135" rpy="0 0 0"/>
    <mass value="0.04601290050153535"/>
    <inertia ixx="8.000440624561934e-06" iyy="7.683397982049525e-06" izz="1.257471080074238e-05" ixy="-2.7077996425010995e-08" iyz="-2.5059571388472146e-15" ixz="-3.729655473350135e-17"/>
  </inertial>
  <visual>
    <origin xyz="0.1297 -0.0181 -0.039315" rpy="0 0 0"/>
    <geometry>
      <mesh filename="meshes/BL_femur_servo_v11.stl" scale="0.001 0.001 0.001"/>
    </geometry>
    <material name="silver"/>
    <material/>
  </visual>
  <collision>
    <origin xyz="0.1297 -0.0181 -0.039315" rpy="0 0 0"/>
    <geometry>
      <mesh filename="meshes/BL_femur_servo_v11.stl" scale="0.001 0.001 0.001"/>
    </geometry>
  </collision>
</link>

<link name="BL_leg_knee_up_v11">
  <inertial>
    <origin xyz="-0.008186450135887174 -0.03333796413791295 -0.03273825100187153" rpy="0 0 0"/>
    <mass value="0.0166380341089574"/>
    <inertia ixx="1.4973159103528296e-05" iyy="7.831104039048996e-06" izz="8.151900973265148e-06" ixy="2.0657848576850023e-07" iyz="-7.202098162942318e-06" ixz="2.0849813871795997e-07"/>
  </inertial>
  <visual>
    <origin xyz="0.1403 -0.0329 -0.044315" rpy="0 0 0"/>
    <geometry>
      <mesh filename="meshes/BL_leg_knee_up_v11.stl" scale="0.001 0.001 0.001"/>
    </geometry>
    <material name="silver"/>
    <material/>
  </visual>
  <collision>
    <origin xyz="0.1403 -0.0329 -0.044315" rpy="0 0 0"/>
    <geometry>
      <mesh filename="meshes/BL_leg_knee_up_v11.stl" scale="0.001 0.001 0.001"/>
    </geometry>
  </collision>
</link>

<link name="BL_leg_ankle_v11">
  <inertial>
    <origin xyz="0.006599671423149683 0.03633185853490647 -0.030777855602896247" rpy="0 0 0"/>
    <mass value="0.022209946665644437"/>
    <inertia ixx="1.8142218155355465e-05" iyy="8.758864927658236e-06" izz="1.2497646484325748e-05" ixy="7.136090776318138e-11" iyz="8.477773878468615e-06" ixz="-2.1616187783962335e-10"/>
  </inertial>
  <visual>
    <origin xyz="0.1533 0.029588 0.021258" rpy="0 0 0"/>
    <geometry>
      <mesh filename="meshes/BL_leg_ankle_v11.stl" scale="0.001 0.001 0.001"/>
    </geometry>
    <material name="silver"/>
    <material/>
  </visual>
  <collision>
    <origin xyz="0.1533 0.029588 0.021258" rpy="0 0 0"/>
    <geometry>
      <mesh filename="meshes/BL_leg_ankle_v11.stl" scale="0.001 0.001 0.001"/>
    </geometry>
  </collision>
</link>

<link name="BL_foot1">
  <inertial>
    <origin xyz="-1.37100539309154e-05 -8.155967483325366e-08 -0.004683879626901949" rpy="0 0 0"/>
    <mass value="0.03203586218872173"/>
    <inertia ixx="1.2963894935669792e-06" iyy="1.296030427783471e-06" izz="1.9992319612345414e-06" ixy="-3.955233493155297e-13" iyz="4.1446138002458523e-10" ixz="4.565430065245346e-13"/>
  </inertial>
  <visual>
    <origin xyz="0.1467 -0.038288 0.080289" rpy="0 0 0"/>
    <geometry>
      <mesh filename="meshes/BL_foot1.stl" scale="0.001 0.001 0.001"/>
    </geometry>
    <material name="silver"/>
    <material/>
  </visual>
  <collision>
    <origin xyz="0.1467 -0.038288 0.080289" rpy="0 0 0"/>
    <geometry>
      <mesh filename="meshes/BL_foot1.stl" scale="0.001 0.001 0.001"/>
    </geometry>
  </collision>
</link>

<link name="BL_tip_foot1">
  <inertial>
    <origin xyz="1.4000512477435612e-05 -5.331310200578504e-05 -0.021949945389569528" rpy="0 0 0"/>
    <mass value="6.16537558266988e-06"/>
    <inertia ixx="8.991172973528629e-13" iyy="8.991171977867869e-13" izz="7.706718980731129e-13" ixy="1.9852334701272664e-23" iyz="0.0" ixz="-1.3234889800848443e-23"/>
  </inertial>
  <visual>
    <origin xyz="0.146714 -0.038341 0.070289" rpy="0 0 0"/>
    <geometry>
      <mesh filename="meshes/BL_tip_foot1.stl" scale="0.001 0.001 0.001"/>
    </geometry>
    <material name="silver"/>
    <material/>
  </visual>
  <collision>
    <origin xyz="0.146714 -0.038341 0.070289" rpy="0 0 0"/>
    <geometry>
      <mesh filename="meshes/BL_tip_foot1.stl" scale="0.001 0.001 0.001"/>
    </geometry>
  </collision>
</link>

<link name="BR_shoulder_servo_v11">
  <inertial>
    <origin xyz="-0.004999999999906737 0.010978373638995814 0.024635264790648342" rpy="0 0 0"/>
    <mass value="0.04601290048863176"/>
    <inertia ixx="1.2574710791247155e-05" iyy="8.000440619705264e-06" izz="7.683397975878246e-06" ixy="-4.41405809473161e-17" iyz="-2.707799584366179e-08" ixz="3.3966800455208918e-15"/>
  </inertial>
  <visual>
    <origin xyz="0.0055 -0.091873 -0.010595" rpy="0 0 0"/>
    <geometry>
      <mesh filename="meshes/BR_shoulder_servo_v11.stl" scale="0.001 0.001 0.001"/>
    </geometry>
    <material name="silver"/>
    <material/>
  </visual>
  <collision>
    <origin xyz="0.0055 -0.091873 -0.010595" rpy="0 0 0"/>
    <geometry>
      <mesh filename="meshes/BR_shoulder_servo_v11.stl" scale="0.001 0.001 0.001"/>
    </geometry>
  </collision>
</link>

<link name="BR_shoulder_servo_arm_v11">
  <inertial>
    <origin xyz="1.4778291014389683e-05 -0.003182518476422827 0.007872032785530586" rpy="0 0 0"/>
    <mass value="0.003270100372952749"/>
    <inertia ixx="3.264260085700882e-07" iyy="3.543164257982531e-07" izz="4.503532148538472e-08" ixy="-3.977690578175e-11" iyz="2.5082435760458453e-09" ixz="-4.0594453569333806e-09"/>
  </inertial>
  <visual>
    <origin xyz="0.0105 -0.081273 -0.025395" rpy="0 0 0"/>
    <geometry>
      <mesh filename="meshes/BR_shoulder_servo_arm_v11.stl" scale="0.001 0.001 0.001"/>
    </geometry>
    <material name="silver"/>
    <material/>
  </visual>
  <collision>
    <origin xyz="0.0105 -0.081273 -0.025395" rpy="0 0 0"/>
    <geometry>
      <mesh filename="meshes/BR_shoulder_servo_arm_v11.stl" scale="0.001 0.001 0.001"/>
    </geometry>
  </collision>
</link>

<link name="BR_leg_hip_servo_holder_v11">
  <inertial>
    <origin xyz="-0.0003103970836539176 -0.029675564171081706 0.014851204620871139" rpy="0 0 0"/>
    <mass value="0.03584481537828423"/>
    <inertia ixx="2.96365732017768e-05" iyy="1.0655535802277775e-05" izz="2.4254678096070114e-05" ixy="-3.1194383537498595e-08" iyz="1.8986820863493576e-06" ixz="-7.417973162695041e-08"/>
  </inertial>
  <visual>
    <origin xyz="0.0105 -0.075473 -0.025395" rpy="0 0 0"/>
    <geometry>
      <mesh filename="meshes/BR_leg_hip_servo_holder_v11.stl" scale="0.001 0.001 0.001"/>
    </geometry>
    <material name="silver"/>
    <material/>
  </visual>
  <collision>
    <origin xyz="0.0105 -0.075473 -0.025395" rpy="0 0 0"/>
    <geometry>
      <mesh filename="meshes/BR_leg_hip_servo_holder_v11.stl" scale="0.001 0.001 0.001"/>
    </geometry>
  </collision>
</link>

<link name="BR_femur_servo_v11">
  <inertial>
    <origin xyz="-0.010978371357005062 -0.02496444119100899 -0.004999642027081433" rpy="0 0 0"/>
    <mass value="0.046012900501535337"/>
    <inertia ixx="8.000440624561826e-06" iyy="7.68339798204939e-06" izz="1.2574710800742313e-05" ixy="2.70779964250957e-08" iyz="-2.5059164812657464e-15" ixz="3.7340600446758576e-17"/>
  </inertial>
  <visual>
    <origin xyz="0.0023 -0.0671 -0.049315" rpy="0 0 0"/>
    <geometry>
      <mesh filename="meshes/BR_femur_servo_v11.stl" scale="0.001 0.001 0.001"/>
    </geometry>
    <material name="silver"/>
    <material/>
  </visual>
  <collision>
    <origin xyz="0.0023 -0.0671 -0.049315" rpy="0 0 0"/>
    <geometry>
      <mesh filename="meshes/BR_femur_servo_v11.stl" scale="0.001 0.001 0.001"/>
    </geometry>
  </collision>
</link>

<link name="BR_leg_knee_up_v11">
  <inertial>
    <origin xyz="0.008186450675841872 -0.03333796566138478 -0.03273825548829235" rpy="0 0 0"/>
    <mass value="0.01663804691396025"/>
    <inertia ixx="1.4973165580154284e-05" iyy="7.831108529663758e-06" izz="8.15190398040124e-06" ixy="-2.065783004369929e-07" iyz="-7.202101187504959e-06" ixz="-2.0849804666921881e-07"/>
  </inertial>
  <visual>
    <origin xyz="-0.0083 -0.0323 -0.044315" rpy="0 0 0"/>
    <geometry>
      <mesh filename="meshes/BR_leg_knee_up_v11.stl" scale="0.001 0.001 0.001"/>
    </geometry>
    <material name="silver"/>
    <material/>
  </visual>
  <collision>
    <origin xyz="-0.0083 -0.0323 -0.044315" rpy="0 0 0"/>
    <geometry>
      <mesh filename="meshes/BR_leg_knee_up_v11.stl" scale="0.001 0.001 0.001"/>
    </geometry>
  </collision>
</link>

<link name="BR_tibia_servo_v11">
  <inertial>
    <origin xyz="-0.01097837374119087 0.02496443940279416 0.0050003579727485765" rpy="0 0 0"/>
    <mass value="0.046012900501535337"/>
    <inertia ixx="8.000440624561907e-06" iyy="7.683397982049423e-06" izz="1.2574710800742367e-05" ixy="-2.7077996425099087e-08" iyz="-2.5059503625836366e-15" ixz="-3.733551824907505e-17"/>
  </inertial>
  <visual>
    <origin xyz="0.0023 -0.0181 -0.018815" rpy="0 0 0"/>
    <geometry>
      <mesh filename="meshes/BR_tibia_servo_v11.stl" scale="0.001 0.001 0.001"/>
    </geometry>
    <material name="silver"/>
    <material/>
  </visual>
  <collision>
    <origin xyz="0.0023 -0.0181 -0.018815" rpy="0 0 0"/>
    <geometry>
      <mesh filename="meshes/BR_tibia_servo_v11.stl" scale="0.001 0.001 0.001"/>
    </geometry>
  </collision>
</link>

<link name="BR_tip_foot1">
  <inertial>
    <origin xyz="0.05198800228875158 0.08332368689799408 0.08630405461043009" rpy="0 0 0"/>
    <mass value="6.16537558266988e-06"/>
    <inertia ixx="8.991172972999233e-13" iyy="8.991171979853102e-13" izz="7.706718982666732e-13" ixy="-2.895132143935597e-24" iyz="-6.617444900424222e-24" ixz="1.6543612251060553e-24"/>
  </inertial>
  <visual>
    <origin xyz="0.037088 0.045636 0.178543" rpy="0 0 0"/>
    <geometry>
      <mesh filename="meshes/BR_tip_foot1.stl" scale="0.001 0.001 0.001"/>
    </geometry>
    <material name="silver"/>
    <material/>
  </visual>
  <collision>
    <origin xyz="0.037088 0.045636 0.178543" rpy="0 0 0"/>
    <geometry>
      <mesh filename="meshes/BR_tip_foot1.stl" scale="0.001 0.001 0.001"/>
    </geometry>
  </collision>
</link>

<link name="FL_shoulder_servo_v11">
  <inertial>
    <origin xyz="-0.005000000000094831 -0.010978458148605458 0.02463537492765486" rpy="0 0 0"/>
    <mass value="0.04601290050153535"/>
    <inertia ixx="1.2574710800742489e-05" iyy="8.000440624561555e-06" izz="7.683397982049091e-06" ixy="-3.74049749507499e-17" iyz="2.7077996425065205e-08" ixz="2.5059435863200585e-15"/>
  </inertial>
  <visual>
    <origin xyz="0.1165 -0.172127 -0.010564" rpy="0 0 0"/>
    <geometry>
      <mesh filename="meshes/FL_shoulder_servo_v11.stl" scale="0.001 0.001 0.001"/>
    </geometry>
    <material name="silver"/>
    <material/>
  </visual>
  <collision>
    <origin xyz="0.1165 -0.172127 -0.010564" rpy="0 0 0"/>
    <geometry>
      <mesh filename="meshes/FL_shoulder_servo_v11.stl" scale="0.001 0.001 0.001"/>
    </geometry>
  </collision>
</link>

<link name="FL_shoulder_servo_arm_v11">
  <inertial>
    <origin xyz="-1.4774595671396273e-05 0.00318243770459542 0.007872147248173294" rpy="0 0 0"/>
    <mass value="0.003270096931145701"/>
    <inertia ixx="3.264258884250274e-07" iyy="3.543162629485389e-07" izz="4.503522072063092e-08" ixy="-3.980726601755975e-11" iyz="-2.5081215526776696e-09" ixz="4.05946458851681e-09"/>
  </inertial>
  <visual>
    <origin xyz="0.1215 -0.182727 -0.025364" rpy="0 0 0"/>
    <geometry>
      <mesh filename="meshes/FL_shoulder_servo_arm_v11.stl" scale="0.001 0.001 0.001"/>
    </geometry>
    <material name="silver"/>
    <material/>
  </visual>
  <collision>
    <origin xyz="0.1215 -0.182727 -0.025364" rpy="0 0 0"/>
    <geometry>
      <mesh filename="meshes/FL_shoulder_servo_arm_v11.stl" scale="0.001 0.001 0.001"/>
    </geometry>
  </collision>
</link>

<link name="BR_foot1">
  <inertial>
    <origin xyz="2.288856089036062e-09 -3.1507249873899412e-06 -0.004688447764353121" rpy="0 0 0"/>
    <mass value="0.032103076351745446"/>
    <inertia ixx="1.2999992826350079e-06" iyy="1.3012507208091787e-06" izz="2.0056908572058734e-06" ixy="1.0164395367051604e-20" iyz="3.517273810394036e-10" ixz="-2.710505431213761e-20"/>
  </inertial>
  <visual>
    <origin xyz="-0.0149 -0.037688 0.080289" rpy="0 0 0"/>
    <geometry>
      <mesh filename="meshes/BR_foot1.stl" scale="0.001 0.001 0.001"/>
    </geometry>
    <material name="silver"/>
    <material/>
  </visual>
  <collision>
    <origin xyz="-0.0149 -0.037688 0.080289" rpy="0 0 0"/>
    <geometry>
      <mesh filename="meshes/BR_foot1.stl" scale="0.001 0.001 0.001"/>
    </geometry>
  </collision>
</link>

<link name="FL_tip_foot1">
  <inertial>
    <origin xyz="-0.23078799990477367 0.24512360418342663 -0.07430483525198046" rpy="0 0 0"/>
    <mass value="6.16537558266988e-06"/>
    <inertia ixx="8.991172973660978e-13" iyy="8.99117198130894e-13" izz="7.706718984966294e-13" ixy="-2.6469779601696886e-23" iyz="2.6469779601696886e-23" ixz="0.0"/>
  </inertial>
  <visual>
    <origin xyz="-0.083888 0.028636 0.017965" rpy="0 0 0"/>
    <geometry>
      <mesh filename="meshes/FL_tip_foot1.stl" scale="0.001 0.001 0.001"/>
    </geometry>
    <material name="silver"/>
    <material/>
  </visual>
  <collision>
    <origin xyz="-0.083888 0.028636 0.017965" rpy="0 0 0"/>
    <geometry>
      <mesh filename="meshes/FL_tip_foot1.stl" scale="0.001 0.001 0.001"/>
    </geometry>
  </collision>
</link>

<link name="FL_foot1">
  <inertial>
    <origin xyz="9.533090983282477e-11 -3.2334760595997825e-06 -0.004688338161605687" rpy="0 0 0"/>
    <mass value="0.03210308702051613"/>
    <inertia ixx="1.299999993479477e-06" iyy="1.3012514464865637e-06" izz="2.0056919635782523e-06" ixy="0.0" iyz="3.51731858048987e-10" ixz="5.421010862427522e-20"/>
  </inertial>
  <visual>
    <origin xyz="0.1469 -0.216488 0.08032" rpy="0 0 0"/>
    <geometry>
      <mesh filename="meshes/FL_foot1.stl" scale="0.001 0.001 0.001"/>
    </geometry>
    <material name="silver"/>
    <material/>
  </visual>
  <collision>
    <origin xyz="0.1469 -0.216488 0.08032" rpy="0 0 0"/>
    <geometry>
      <mesh filename="meshes/FL_foot1.stl" scale="0.001 0.001 0.001"/>
    </geometry>
  </collision>
</link>

<link name="FR_shoulder_servo_v11">
  <inertial>
    <origin xyz="0.0049999995828425795 -0.010978373645823492 0.02463526479006555" rpy="0 0 0"/>
    <mass value="0.046012900501535337"/>
    <inertia ixx="1.2574710800742923e-05" iyy="8.000440624561853e-06" izz="7.683397982049959e-06" ixy="3.7364317369281697e-17" iyz="2.7077996425010995e-08" ixz="-2.5059300337929025e-15"/>
  </inertial>
  <visual>
    <origin xyz="0.0155 -0.172127 -0.010595" rpy="0 0 0"/>
    <geometry>
      <mesh filename="meshes/FR_shoulder_servo_v11.stl" scale="0.001 0.001 0.001"/>
    </geometry>
    <material name="silver"/>
    <material/>
  </visual>
  <collision>
    <origin xyz="0.0155 -0.172127 -0.010595" rpy="0 0 0"/>
    <geometry>
      <mesh filename="meshes/FR_shoulder_servo_v11.stl" scale="0.001 0.001 0.001"/>
    </geometry>
  </collision>
</link>

<link name="FR_shoulder_servo_arm_v11">
  <inertial>
    <origin xyz="1.4777879760893148e-05 0.003382518491762354 0.007872032785530572" rpy="0 0 0"/>
    <mass value="0.0032701003729527518"/>
    <inertia ixx="3.264260121132778e-07" iyy="3.5431642633774954e-07" izz="4.503532556810385e-08" ixy="3.977552319019899e-11" iyz="-2.5082431811573912e-09" ixz="-4.059445202506145e-09"/>
  </inertial>
  <visual>
    <origin xyz="0.0105 -0.182727 -0.025395" rpy="0 0 0"/>
    <geometry>
      <mesh filename="meshes/FR_shoulder_servo_arm_v11.stl" scale="0.001 0.001 0.001"/>
    </geometry>
    <material name="silver"/>
    <material/>
  </visual>
  <collision>
    <origin xyz="0.0105 -0.182727 -0.025395" rpy="0 0 0"/>
    <geometry>
      <mesh filename="meshes/FR_shoulder_servo_arm_v11.stl" scale="0.001 0.001 0.001"/>
    </geometry>
  </collision>
</link>

<link name="FR_leg_hip_servo_holder_v11">
  <inertial>
    <origin xyz="-0.0003103177867561629 0.02966882097851517 0.014847477048963373" rpy="0 0 0"/>
    <mass value="0.035853832339797095"/>
    <inertia ixx="2.964507741737765e-05" iyy="1.065754704355732e-05" izz="2.4261196501281423e-05" ixy="3.127060520102126e-08" iyz="-1.9022651394532222e-06" ixz="-7.413870955669502e-08"/>
  </inertial>
  <visual>
    <origin xyz="0.0105 -0.188727 -0.025395" rpy="0 0 0"/>
    <geometry>
      <mesh filename="meshes/FR_leg_hip_servo_holder_v11.stl" scale="0.001 0.001 0.001"/>
    </geometry>
    <material name="silver"/>
    <material/>
  </visual>
  <collision>
    <origin xyz="0.0105 -0.188727 -0.025395" rpy="0 0 0"/>
    <geometry>
      <mesh filename="meshes/FR_leg_hip_servo_holder_v11.stl" scale="0.001 0.001 0.001"/>
    </geometry>
  </collision>
</link>

<link name="FR_femur_servo_v11">
  <inertial>
    <origin xyz="-0.01097837177425732 0.02463556059720587 -0.004999642027081516" rpy="0 0 0"/>
    <mass value="0.046012900501535337"/>
    <inertia ixx="8.000440624561771e-06" iyy="7.683397982049444e-06" izz="1.2574710800742489e-05" ixy="2.7077996425119415e-08" iyz="-2.5060791115916192e-15" ixz="3.7343988578547593e-17"/>
  </inertial>
  <visual>
    <origin xyz="0.0023 -0.1971 -0.049315" rpy="0 0 0"/>
    <geometry>
      <mesh filename="meshes/FR_femur_servo_v11.stl" scale="0.001 0.001 0.001"/>
    </geometry>
    <material name="silver"/>
    <material/>
  </visual>
  <collision>
    <origin xyz="0.0023 -0.1971 -0.049315" rpy="0 0 0"/>
    <geometry>
      <mesh filename="meshes/FR_femur_servo_v11.stl" scale="0.001 0.001 0.001"/>
    </geometry>
  </collision>
</link>

<link name="FR_tibia_servo_v11">
  <inertial>
    <origin xyz="-0.010978371774257306 0.02463556059720587 -0.004999642027081461" rpy="0 0 0"/>
    <mass value="0.046012900501535337"/>
    <inertia ixx="8.000440624562205e-06" iyy="7.68339798204943e-06" izz="1.2574710800742489e-05" ixy="2.7077996425065205e-08" iyz="-2.5058893762114343e-15" ixz="3.7328741985497016e-17"/>
  </inertial>
  <visual>
    <origin xyz="0.0023 -0.1971 -0.028815" rpy="0 0 0"/>
    <geometry>
      <mesh filename="meshes/FR_tibia_servo_v11.stl" scale="0.001 0.001 0.001"/>
    </geometry>
    <material name="silver"/>
    <material/>
  </visual>
  <collision>
    <origin xyz="0.0023 -0.1971 -0.028815" rpy="0 0 0"/>
    <geometry>
      <mesh filename="meshes/FR_tibia_servo_v11.stl" scale="0.001 0.001 0.001"/>
    </geometry>
  </collision>
</link>

<link name="FR_leg_knee_up_v11">
  <inertial>
    <origin xyz="0.008186450258589608 -0.033337963873169896 -0.03273825548829235" rpy="0 0 0"/>
    <mass value="0.01663804691396025"/>
    <inertia ixx="1.4973165580153911e-05" iyy="7.831108529663626e-06" izz="8.151903980401463e-06" ixy="-2.065783004369948e-07" iyz="-7.20210118750502e-06" ixz="-2.0849804666922305e-07"/>
  </inertial>
  <visual>
    <origin xyz="-0.0083 -0.2119 -0.044315" rpy="0 0 0"/>
    <geometry>
      <mesh filename="meshes/FR_leg_knee_up_v11.stl" scale="0.001 0.001 0.001"/>
    </geometry>
    <material name="silver"/>
    <material/>
  </visual>
  <collision>
    <origin xyz="-0.0083 -0.2119 -0.044315" rpy="0 0 0"/>
    <geometry>
      <mesh filename="meshes/FR_leg_knee_up_v11.stl" scale="0.001 0.001 0.001"/>
    </geometry>
  </collision>
</link>

<link name="FR_leg_ankle_v11">
  <inertial>
    <origin xyz="0.006600332709766968 0.0363318051633027 -0.03077780621827081" rpy="0 0 0"/>
    <mass value="0.022209898104400553"/>
    <inertia ixx="1.814216094624913e-05" iyy="8.758836859265926e-06" izz="1.249761147303235e-05" ixy="-7.25926106606798e-11" iyz="8.477746015364942e-06" ixz="2.173650679885902e-10"/>
  </inertial>
  <visual>
    <origin xyz="-0.0083 -0.149412 0.021258" rpy="0 0 0"/>
    <geometry>
      <mesh filename="meshes/FR_leg_ankle_v11.stl" scale="0.001 0.001 0.001"/>
    </geometry>
    <material name="silver"/>
    <material/>
  </visual>
  <collision>
    <origin xyz="-0.0083 -0.149412 0.021258" rpy="0 0 0"/>
    <geometry>
      <mesh filename="meshes/FR_leg_ankle_v11.stl" scale="0.001 0.001 0.001"/>
    </geometry>
  </collision>
</link>

<link name="FR_tip_foot1">
  <inertial>
    <origin xyz="0.2315880018714994 0.08332368868620879 0.08627405461043021" rpy="0 0 0"/>
    <mass value="6.165375582669441e-06"/>
    <inertia ixx="8.991172974719769e-13" iyy="8.99117197833109e-13" izz="7.70671898178992e-13" ixy="3.308722450212111e-24" iyz="2.6469779601696886e-23" ixz="0.0"/>
  </inertial>
  <visual>
    <origin xyz="0.216688 -0.133964 0.178543" rpy="0 0 0"/>
    <geometry>
      <mesh filename="meshes/FR_tip_foot1.stl" scale="0.001 0.001 0.001"/>
    </geometry>
    <material name="silver"/>
    <material/>
  </visual>
  <collision>
    <origin xyz="0.216688 -0.133964 0.178543" rpy="0 0 0"/>
    <geometry>
      <mesh filename="meshes/FR_tip_foot1.stl" scale="0.001 0.001 0.001"/>
    </geometry>
  </collision>
</link>

<link name="FR_foot1">
  <inertial>
    <origin xyz="1.610972258370147e-09 -7.470582641389001e-08 -0.004686863229863059" rpy="0 0 0"/>
    <mass value="0.032106697385340256"/>
    <inertia ixx="1.3013552658286843e-06" iyy="1.3008349106742383e-06" izz="2.0066494720732703e-06" ixy="5.731892824961671e-13" iyz="2.4224604310355002e-11" ixz="-2.668426189646883e-14"/>
  </inertial>
  <visual>
    <origin xyz="-0.0149 -0.217288 0.080289" rpy="0 0 0"/>
    <geometry>
      <mesh filename="meshes/FR_foot1.stl" scale="0.001 0.001 0.001"/>
    </geometry>
    <material name="silver"/>
    <material/>
  </visual>
  <collision>
    <origin xyz="-0.0149 -0.217288 0.080289" rpy="0 0 0"/>
    <geometry>
      <mesh filename="meshes/FR_foot1.stl" scale="0.001 0.001 0.001"/>
    </geometry>
  </collision>
</link>

<link name="BR_leg_ankle_v11">
  <inertial>
    <origin xyz="0.0066003331270191555 0.03633180337508777 -0.03077780621827081" rpy="0 0 0"/>
    <mass value="0.022209898104400553"/>
    <inertia ixx="1.8142160946248303e-05" iyy="8.758836859266034e-06" izz="1.2497611473032574e-05" ixy="-7.259261065263299e-11" iyz="8.477746015365e-06" ixz="2.1736506797503767e-10"/>
  </inertial>
  <visual>
    <origin xyz="-0.0083 0.030188 0.021258" rpy="0 0 0"/>
    <geometry>
      <mesh filename="meshes/BR_leg_ankle_v11.stl" scale="0.001 0.001 0.001"/>
    </geometry>
    <material name="silver"/>
    <material/>
  </visual>
  <collision>
    <origin xyz="-0.0083 0.030188 0.021258" rpy="0 0 0"/>
    <geometry>
      <mesh filename="meshes/BR_leg_ankle_v11.stl" scale="0.001 0.001 0.001"/>
    </geometry>
  </collision>
</link>

<link name="BL_tibia_servo_v11">
  <inertial>
    <origin xyz="0.01097837415844323 0.024964439402794133 0.005000357972748601" rpy="0 0 0"/>
    <mass value="0.04601290050153535"/>
    <inertia ixx="8.000440624561934e-06" iyy="7.683397982049416e-06" izz="1.2574710800742272e-05" ixy="2.7077996425065205e-08" iyz="-2.5059639151107926e-15" ixz="3.724234462487708e-17"/>
  </inertial>
  <visual>
    <origin xyz="0.1297 -0.0181 -0.018815" rpy="0 0 0"/>
    <geometry>
      <mesh filename="meshes/BL_tibia_servo_v11.stl" scale="0.001 0.001 0.001"/>
    </geometry>
    <material name="silver"/>
    <material/>
  </visual>
  <collision>
    <origin xyz="0.1297 -0.0181 -0.018815" rpy="0 0 0"/>
    <geometry>
      <mesh filename="meshes/BL_tibia_servo_v11.stl" scale="0.001 0.001 0.001"/>
    </geometry>
  </collision>
</link>

<link name="FL_leg_hip_servo_holder_v11">
  <inertial>
    <origin xyz="0.00031031736950724864 0.029668736475733343 0.014847587186552508" rpy="0 0 0"/>
    <mass value="0.0358538323397971"/>
    <inertia ixx="2.964507741737483e-05" iyy="1.065754704355419e-05" izz="2.426119650128164e-05" ixy="-3.127060519845983e-08" iyz="-1.9022651394531138e-06" ixz="7.413870955645446e-08"/>
  </inertial>
  <visual>
    <origin xyz="0.1215 -0.188527 -0.025364" rpy="0 0 0"/>
    <geometry>
      <mesh filename="meshes/FL_leg_hip_servo_holder_v11.stl" scale="0.001 0.001 0.001"/>
    </geometry>
    <material name="silver"/>
    <material/>
  </visual>
  <collision>
    <origin xyz="0.1215 -0.188527 -0.025364" rpy="0 0 0"/>
    <geometry>
      <mesh filename="meshes/FL_leg_hip_servo_holder_v11.stl" scale="0.001 0.001 0.001"/>
    </geometry>
  </collision>
</link>

<link name="FL_femur_servo_v11">
  <inertial>
    <origin xyz="0.010978373741191746 -0.024964523905575686 -0.004999531889492301" rpy="0 0 0"/>
    <mass value="0.04601290050153535"/>
    <inertia ixx="8.000440624563072e-06" iyy="7.683397982049416e-06" izz="1.2574710800742489e-05" ixy="-2.7077996425173625e-08" iyz="-2.506024901482995e-15" ixz="-3.724234462487708e-17"/>
  </inertial>
  <visual>
    <origin xyz="0.1297 -0.2459 -0.049284" rpy="0 0 0"/>
    <geometry>
      <mesh filename="meshes/FL_femur_servo_v11.stl" scale="0.001 0.001 0.001"/>
    </geometry>
    <material name="silver"/>
    <material/>
  </visual>
  <collision>
    <origin xyz="0.1297 -0.2459 -0.049284" rpy="0 0 0"/>
    <geometry>
      <mesh filename="meshes/FL_femur_servo_v11.stl" scale="0.001 0.001 0.001"/>
    </geometry>
  </collision>
</link>

<link name="FL_tibia_servo_v11">
  <inertial>
    <origin xyz="0.010978373747012549 -0.024964523899645097 0.005000468108006643" rpy="0 0 0"/>
    <mass value="0.0460129005147678"/>
    <inertia ixx="8.000440629646246e-06" iyy="7.68339798820595e-06" izz="1.2574710810467783e-05" ixy="-2.7078001838595073e-08" iyz="-2.966566879300525e-15" ixz="2.261808362130635e-15"/>
  </inertial>
  <visual>
    <origin xyz="0.1297 -0.2459 -0.018784" rpy="0 0 0"/>
    <geometry>
      <mesh filename="meshes/FL_tibia_servo_v11.stl" scale="0.001 0.001 0.001"/>
    </geometry>
    <material name="silver"/>
    <material/>
  </visual>
  <collision>
    <origin xyz="0.1297 -0.2459 -0.018784" rpy="0 0 0"/>
    <geometry>
      <mesh filename="meshes/FL_tibia_servo_v11.stl" scale="0.001 0.001 0.001"/>
    </geometry>
  </collision>
</link>

<link name="FL_leg_knee_up_v11">
  <inertial>
    <origin xyz="-0.008186450553138186 -0.033338046852480374 -0.03273814086428243" rpy="0 0 0"/>
    <mass value="0.0166380341089574"/>
    <inertia ixx="1.4973159103524023e-05" iyy="7.831104039046936e-06" izz="8.151900973265365e-06" ixy="2.0657848576823056e-07" iyz="-7.202098162944546e-06" ixz="2.084981387181802e-07"/>
  </inertial>
  <visual>
    <origin xyz="0.1403 -0.2111 -0.044284" rpy="0 0 0"/>
    <geometry>
      <mesh filename="meshes/FL_leg_knee_up_v11.stl" scale="0.001 0.001 0.001"/>
    </geometry>
    <material name="silver"/>
    <material/>
  </visual>
  <collision>
    <origin xyz="0.1403 -0.2111 -0.044284" rpy="0 0 0"/>
    <geometry>
      <mesh filename="meshes/FL_leg_knee_up_v11.stl" scale="0.001 0.001 0.001"/>
    </geometry>
  </collision>
</link>

<link name="FL_leg_ankle_v11">
  <inertial>
    <origin xyz="-0.006600328994101262 0.036331775820339 -0.030777745465307278" rpy="0 0 0"/>
    <mass value="0.022209946665644437"/>
    <inertia ixx="1.8142218155355614e-05" iyy="8.758864927658561e-06" izz="1.2497646484325694e-05" ixy="7.136090795969302e-11" iyz="8.477773878468422e-06" ixz="-2.161618779209385e-10"/>
  </inertial>
  <visual>
    <origin xyz="0.1403 -0.148612 0.021289" rpy="0 0 0"/>
    <geometry>
      <mesh filename="meshes/FL_leg_ankle_v11.stl" scale="0.001 0.001 0.001"/>
    </geometry>
    <material name="silver"/>
    <material/>
  </visual>
  <collision>
    <origin xyz="0.1403 -0.148612 0.021289" rpy="0 0 0"/>
    <geometry>
      <mesh filename="meshes/FL_leg_ankle_v11.stl" scale="0.001 0.001 0.001"/>
    </geometry>
  </collision>
</link>

<joint name="Rigid_1" type="fixed">
  <origin xyz="-0.066 -0.003 0.004" rpy="0 0 0"/>
  <parent link="base_link"/>
  <child link="final_body_right_v11"/>
</joint>

<joint name="Rigid_2" type="fixed">
  <origin xyz="-0.1032 -0.003 0.06253" rpy="0 0 0"/>
  <parent link="base_link"/>
  <child link="final_body_top_back_v11"/>
</joint>

<joint name="Rigid_3" type="fixed">
  <origin xyz="0.0372 0.27 0.05853" rpy="0 0 0"/>
  <parent link="final_body_right_v11"/>
  <child link="final_body_top_front_v11"/>
</joint>

<joint name="Rigid_4" type="fixed">
  <origin xyz="0.0 0.27 -0.004" rpy="0 0 0"/>
  <parent link="final_body_right_v11"/>
  <child link="final_body_face_v11"/>
</joint>

<joint name="Rigid_5" type="fixed">
  <origin xyz="-0.066 -0.003 0.0" rpy="0 0 0"/>
  <parent link="base_link"/>
  <child link="final_body_ass_v11"/>
</joint>

<joint name="Rigid_6" type="fixed">
  <origin xyz="-0.1265 0.091873 0.010595" rpy="0 0 0"/>
  <parent link="base_link"/>
  <child link="BL_shoulder_servo_v11"/>
</joint>

<joint name="BL_shoulder_joint" type="continuous">
  <origin xyz="0.005 -0.0106 0.0148" rpy="0 0 0"/>
  <parent link="BL_shoulder_servo_v11"/>
  <child link="BL_shoulder_servo_arm_v11"/>
  <axis xyz="-0.0 1.0 -0.0"/>
</joint>
<transmission name="BL_shoulder_joint_tran">
  <type>transmission_interface/SimpleTransmission</type>
  <joint name="BL_shoulder_joint">
    <hardwareInterface>PositionJointInterface</hardwareInterface>
  </joint>
  <actuator name="BL_shoulder_joint_actr">
    <hardwareInterface>PositionJointInterface</hardwareInterface>
    <mechanicalReduction>1</mechanicalReduction>
  </actuator>
</transmission>

<joint name="Rigid_8" type="fixed">
  <origin xyz="0.0 -0.0058 0.0" rpy="0 0 0"/>
  <parent link="BL_shoulder_servo_arm_v11"/>
  <child link="BL_leg_hip_servo_holder_v11"/>
</joint>

<joint name="Rigid_9" type="fixed">
  <origin xyz="-0.0082 -0.057373 0.01392" rpy="0 0 0"/>
  <parent link="BL_leg_hip_servo_holder_v11"/>
  <child link="BL_femur_servo_v11"/>
</joint>

<joint name="BL_femur_joint" type="continuous">
  <origin xyz="-0.0106 0.0148 0.005" rpy="0 0 0"/>
  <parent link="BL_femur_servo_v11"/>
  <child link="BL_leg_knee_up_v11"/>
  <axis xyz="-1.0 -0.0 -0.0"/>
</joint>
<transmission name="BL_femur_joint_tran">
  <type>transmission_interface/SimpleTransmission</type>
  <joint name="BL_femur_joint">
    <hardwareInterface>PositionJointInterface</hardwareInterface>
  </joint>
  <actuator name="BL_femur_joint_actr">
    <hardwareInterface>PositionJointInterface</hardwareInterface>
    <mechanicalReduction>1</mechanicalReduction>
  </actuator>
</transmission>

<joint name="BL_knee_joint" type="continuous">
  <origin xyz="-0.013 -0.062488 -0.065573" rpy="0 0 0"/>
  <parent link="BL_leg_knee_up_v11"/>
  <child link="BL_leg_ankle_v11"/>
  <axis xyz="-1.0 -0.0 -0.0"/>
</joint>
<transmission name="BL_knee_joint_tran">
  <type>transmission_interface/SimpleTransmission</type>
  <joint name="BL_knee_joint">
    <hardwareInterface>PositionJointInterface</hardwareInterface>
  </joint>
  <actuator name="BL_knee_joint_actr">
    <hardwareInterface>PositionJointInterface</hardwareInterface>
    <mechanicalReduction>1</mechanicalReduction>
  </actuator>
</transmission>

<joint name="Rigid_12" type="fixed">
  <origin xyz="0.0066 0.067876 -0.059031" rpy="0 0 0"/>
  <parent link="BL_leg_ankle_v11"/>
  <child link="BL_foot1"/>
</joint>

<joint name="BL_foot" type="fixed">
  <origin xyz="-1.4e-05 5.3e-05 0.01" rpy="0 0 0"/>
  <parent link="BL_foot1"/>
  <child link="BL_tip_foot1"/>
</joint>

<joint name="Rigid_15" type="fixed">
  <origin xyz="0.0605 0.094873 0.006595" rpy="0 0 0"/>
  <parent link="final_body_right_v11"/>
  <child link="BR_shoulder_servo_v11"/>
</joint>

<joint name="BR_shoulder_joint" type="continuous">
  <origin xyz="-0.005 -0.0106 0.0148" rpy="0 0 0"/>
  <parent link="BR_shoulder_servo_v11"/>
  <child link="BR_shoulder_servo_arm_v11"/>
  <axis xyz="0.0 -1.0 0.0"/>
</joint>
<transmission name="BR_shoulder_joint_tran">
  <type>transmission_interface/SimpleTransmission</type>
  <joint name="BR_shoulder_joint">
    <hardwareInterface>PositionJointInterface</hardwareInterface>
  </joint>
  <actuator name="BR_shoulder_joint_actr">
    <hardwareInterface>PositionJointInterface</hardwareInterface>
    <mechanicalReduction>1</mechanicalReduction>
  </actuator>
</transmission>

<joint name="Rigid_17" type="fixed">
  <origin xyz="0.0 -0.0058 0.0" rpy="0 0 0"/>
  <parent link="BR_shoulder_servo_arm_v11"/>
  <child link="BR_leg_hip_servo_holder_v11"/>
</joint>

<joint name="Rigid_18" type="fixed">
  <origin xyz="0.0082 -0.008373 0.02392" rpy="0 0 0"/>
  <parent link="BR_leg_hip_servo_holder_v11"/>
  <child link="BR_femur_servo_v11"/>
</joint>

<joint name="BR_femur_joint" type="continuous">
  <origin xyz="0.0106 -0.0348 -0.005" rpy="0 0 0"/>
  <parent link="BR_femur_servo_v11"/>
  <child link="BR_leg_knee_up_v11"/>
  <axis xyz="-1.0 -0.0 0.0"/>
</joint>
<transmission name="BR_femur_joint_tran">
  <type>transmission_interface/SimpleTransmission</type>
  <joint name="BR_femur_joint">
    <hardwareInterface>PositionJointInterface</hardwareInterface>
  </joint>
  <actuator name="BR_femur_joint_actr">
    <hardwareInterface>PositionJointInterface</hardwareInterface>
    <mechanicalReduction>1</mechanicalReduction>
  </actuator>
</transmission>

<joint name="Rigid_20" type="fixed">
  <origin xyz="0.0082 -0.057373 -0.00658" rpy="0 0 0"/>
  <parent link="BR_leg_hip_servo_holder_v11"/>
  <child link="BR_tibia_servo_v11"/>
</joint>

<joint name="BR_foot" type="fixed">
  <origin xyz="-0.045388 -0.015448 -0.157285" rpy="0 0 0"/>
  <parent link="BR_leg_ankle_v11"/>
  <child link="BR_tip_foot1"/>
</joint>

<joint name="Rigid_23" type="fixed">
  <origin xyz="-0.1165 0.172127 0.010564" rpy="0 0 0"/>
  <parent link="base_link"/>
  <child link="FL_shoulder_servo_v11"/>
</joint>

<joint name="FL_shoulder_joint" type="continuous">
  <origin xyz="-0.005 0.0106 0.0148" rpy="0 0 0"/>
  <parent link="FL_shoulder_servo_v11"/>
  <child link="FL_shoulder_servo_arm_v11"/>
  <axis xyz="-0.0 1.0 0.0"/>
</joint>
<transmission name="FL_shoulder_joint_tran">
  <type>transmission_interface/SimpleTransmission</type>
  <joint name="FL_shoulder_joint">
    <hardwareInterface>PositionJointInterface</hardwareInterface>
  </joint>
  <actuator name="FL_shoulder_joint_actr">
    <hardwareInterface>PositionJointInterface</hardwareInterface>
    <mechanicalReduction>1</mechanicalReduction>
  </actuator>
</transmission>

<joint name="Rigid_29" type="fixed">
  <origin xyz="0.0066 0.067876 -0.059031" rpy="0 0 0"/>
  <parent link="BR_leg_ankle_v11"/>
  <child link="BR_foot1"/>
</joint>

<joint name="FL_foot" type="fixed">
  <origin xyz="0.224188 -0.177248 0.003324" rpy="0 0 0"/>
  <parent link="FL_leg_ankle_v11"/>
  <child link="FL_tip_foot1"/>
</joint>

<joint name="Rigid_33" type="fixed">
  <origin xyz="-0.0066 0.067876 -0.059031" rpy="0 0 0"/>
  <parent link="FL_leg_ankle_v11"/>
  <child link="FL_foot1"/>
</joint>

<joint name="Rigid_34" type="fixed">
  <origin xyz="0.0505 0.175127 0.006595" rpy="0 0 0"/>
  <parent link="final_body_right_v11"/>
  <child link="FR_shoulder_servo_v11"/>
</joint>

<joint name="FR_shoulder_joint" type="continuous">
  <origin xyz="0.005 0.0106 0.0148" rpy="0 0 0"/>
  <parent link="FR_shoulder_servo_v11"/>
  <child link="FR_shoulder_servo_arm_v11"/>
  <axis xyz="0.0 -1.0 0.0"/>
</joint>
<transmission name="FR_shoulder_joint_tran">
  <type>transmission_interface/SimpleTransmission</type>
  <joint name="FR_shoulder_joint">
    <hardwareInterface>PositionJointInterface</hardwareInterface>
  </joint>
  <actuator name="FR_shoulder_joint_actr">
    <hardwareInterface>PositionJointInterface</hardwareInterface>
    <mechanicalReduction>1</mechanicalReduction>
  </actuator>
</transmission>

<joint name="Rigid_36" type="fixed">
  <origin xyz="0.0 0.006 0.0" rpy="0 0 0"/>
  <parent link="FR_shoulder_servo_arm_v11"/>
  <child link="FR_leg_hip_servo_holder_v11"/>
</joint>

<joint name="Rigid_37" type="fixed">
  <origin xyz="0.0082 0.008373 0.02392" rpy="0 0 0"/>
  <parent link="FR_leg_hip_servo_holder_v11"/>
  <child link="FR_femur_servo_v11"/>
</joint>

<joint name="Rigid_38" type="fixed">
  <origin xyz="0.0082 0.008373 0.00342" rpy="0 0 0"/>
  <parent link="FR_leg_hip_servo_holder_v11"/>
  <child link="FR_tibia_servo_v11"/>
</joint>

<joint name="FR_femur_joint" type="continuous">
  <origin xyz="0.0106 0.0148 -0.005" rpy="0 0 0"/>
  <parent link="FR_femur_servo_v11"/>
  <child link="FR_leg_knee_up_v11"/>
  <axis xyz="-1.0 0.0 -0.0"/>
</joint>
<transmission name="FR_femur_joint_tran">
  <type>transmission_interface/SimpleTransmission</type>
  <joint name="FR_femur_joint">
    <hardwareInterface>PositionJointInterface</hardwareInterface>
  </joint>
  <actuator name="FR_femur_joint_actr">
    <hardwareInterface>PositionJointInterface</hardwareInterface>
    <mechanicalReduction>1</mechanicalReduction>
  </actuator>
</transmission>

<joint name="FR_knee_joint" type="continuous">
  <origin xyz="0.0 -0.062488 -0.065573" rpy="0 0 0"/>
  <parent link="FR_leg_knee_up_v11"/>
  <child link="FR_leg_ankle_v11"/>
  <axis xyz="1.0 -0.0 0.0"/>
</joint>
<transmission name="FR_knee_joint_tran">
  <type>transmission_interface/SimpleTransmission</type>
  <joint name="FR_knee_joint">
    <hardwareInterface>PositionJointInterface</hardwareInterface>
  </joint>
  <actuator name="FR_knee_joint_actr">
    <hardwareInterface>PositionJointInterface</hardwareInterface>
    <mechanicalReduction>1</mechanicalReduction>
  </actuator>
</transmission>

<joint name="FR_foot" type="fixed">
  <origin xyz="-0.224988 -0.015448 -0.157285" rpy="0 0 0"/>
  <parent link="FR_leg_ankle_v11"/>
  <child link="FR_tip_foot1"/>
</joint>

<joint name="Rigid_42" type="fixed">
  <origin xyz="0.0066 0.067876 -0.059031" rpy="0 0 0"/>
  <parent link="FR_leg_ankle_v11"/>
  <child link="FR_foot1"/>
</joint>

<joint name="Revolute_43" type="continuous">
  <origin xyz="0.0 -0.062488 -0.065573" rpy="0 0 0"/>
  <parent link="BR_leg_knee_up_v11"/>
  <child link="BR_leg_ankle_v11"/>
  <axis xyz="1.0 0.0 -0.0"/>
</joint>
<transmission name="Revolute_43_tran">
  <type>transmission_interface/SimpleTransmission</type>
  <joint name="Revolute_43">
    <hardwareInterface>PositionJointInterface</hardwareInterface>
  </joint>
  <actuator name="Revolute_43_actr">
    <hardwareInterface>PositionJointInterface</hardwareInterface>
    <mechanicalReduction>1</mechanicalReduction>
  </actuator>
</transmission>

<joint name="Rigid_44" type="fixed">
  <origin xyz="-0.0082 -0.057373 -0.00658" rpy="0 0 0"/>
  <parent link="BL_leg_hip_servo_holder_v11"/>
  <child link="BL_tibia_servo_v11"/>
</joint>

<joint name="Rigid_45" type="fixed">
  <origin xyz="0.0 0.0058 0.0" rpy="0 0 0"/>
  <parent link="FL_shoulder_servo_arm_v11"/>
  <child link="FL_leg_hip_servo_holder_v11"/>
</joint>

<joint name="Rigid_46" type="fixed">
  <origin xyz="-0.0082 0.057373 0.02392" rpy="0 0 0"/>
  <parent link="FL_leg_hip_servo_holder_v11"/>
  <child link="FL_femur_servo_v11"/>
</joint>

<joint name="Rigid_47" type="fixed">
  <origin xyz="-0.0082 0.057373 -0.00658" rpy="0 0 0"/>
  <parent link="FL_leg_hip_servo_holder_v11"/>
  <child link="FL_tibia_servo_v11"/>
</joint>

<joint name="FL_femur_joint" type="continuous">
  <origin xyz="-0.0106 -0.0348 -0.005" rpy="0 0 0"/>
  <parent link="FL_femur_servo_v11"/>
  <child link="FL_leg_knee_up_v11"/>
  <axis xyz="-1.0 -0.0 -0.0"/>
</joint>
<transmission name="FL_femur_joint_tran">
  <type>transmission_interface/SimpleTransmission</type>
  <joint name="FL_femur_joint">
    <hardwareInterface>PositionJointInterface</hardwareInterface>
  </joint>
  <actuator name="FL_femur_joint_actr">
    <hardwareInterface>PositionJointInterface</hardwareInterface>
    <mechanicalReduction>1</mechanicalReduction>
  </actuator>
</transmission>

<joint name="FL_knee_joint" type="continuous">
  <origin xyz="0.0 -0.062488 -0.065573" rpy="0 0 0"/>
  <parent link="FL_leg_knee_up_v11"/>
  <child link="FL_leg_ankle_v11"/>
  <axis xyz="1.0 0.0 0.0"/>
</joint>
<transmission name="FL_knee_joint_tran">
  <type>transmission_interface/SimpleTransmission</type>
  <joint name="FL_knee_joint">
    <hardwareInterface>PositionJointInterface</hardwareInterface>
  </joint>
  <actuator name="FL_knee_joint_actr">
    <hardwareInterface>PositionJointInterface</hardwareInterface>
    <mechanicalReduction>1</mechanicalReduction>
  </actuator>
</transmission>

</robot>
