<?xml version="1.0" ?>
<robot name="body_urdf">

<material name="silver">
  <color rgba="0.700 0.700 0.700 1.000"/>
</material>

<link name="base_link">
  <inertial>
    <origin xyz="-0.0908793744734593 0.16006598423217536 0.15049638034007085" rpy="0 0 0"/>
    <mass value="2.6867356857453366"/>
    <inertia ixx="0.004723646078211741" iyy="0.02084558554472575" izz="0.022295677973903916" ixy="-7.670959887261242e-06" iyz="-2.708869186185403e-07" ixz="-0.00010958062661201723"/>
  </inertial>
  <visual>
    <origin xyz="0 0 0" rpy="0 0 0"/>
    <geometry>
      <mesh filename="meshes/base_link.stl" scale="0.001 0.001 0.001"/>
    </geometry>
    <material name="silver"/>
    <material/>
  </visual>
  <collision>
    <origin xyz="0 0 0" rpy="0 0 0"/>
    <geometry>
      <mesh filename="meshes/base_link.stl" scale="0.001 0.001 0.001"/>
    </geometry>
  </collision>
</link>

<link name="FR_shoulder_servo_arm1">
  <inertial>
    <origin xyz="-0.0033827804116803584 1.4981274133352152e-05 0.007872318287967112" rpy="0 0 0"/>
    <mass value="0.0032701003729527518"/>
    <inertia ixx="3.5431642633773175e-07" iyy="3.264260121132914e-07" izz="4.503532556813096e-08" ixy="-3.977552318003459e-11" iyz="-4.05944520251271e-09" ixz="2.5082431811607794e-09"/>
  </inertial>
  <visual>
    <origin xyz="0.142 -0.211596 -0.150395" rpy="0 0 0"/>
    <geometry>
      <mesh filename="meshes/FR_shoulder_servo_arm1.stl" scale="0.001 0.001 0.001"/>
    </geometry>
    <material name="silver"/>
    <material/>
  </visual>
  <collision>
    <origin xyz="0.142 -0.211596 -0.150395" rpy="0 0 0"/>
    <geometry>
      <mesh filename="meshes/FR_shoulder_servo_arm1.stl" scale="0.001 0.001 0.001"/>
    </geometry>
  </collision>
</link>

<link name="FR_leg_hip_servo_holder1">
  <inertial>
    <origin xyz="-0.029062249956410657 -0.0007339092135612846 0.015154064659331223" rpy="0 0 0"/>
    <mass value="0.03470303413377985"/>
    <inertia ixx="1.0251432959789298e-05" iyy="2.8593040473580585e-05" izz="2.3342941573267686e-05" ixy="-9.729946632208372e-08" iyz="-1.8050301079123796e-07" ixz="1.9848378024970963e-06"/>
  </inertial>
  <visual>
    <origin xyz="0.148 -0.211596 -0.150395" rpy="0 0 0"/>
    <geometry>
      <mesh filename="meshes/FR_leg_hip_servo_holder1.stl" scale="0.001 0.001 0.001"/>
    </geometry>
    <material name="silver"/>
    <material/>
  </visual>
  <collision>
    <origin xyz="0.148 -0.211596 -0.150395" rpy="0 0 0"/>
    <geometry>
      <mesh filename="meshes/FR_leg_hip_servo_holder1.stl" scale="0.001 0.001 0.001"/>
    </geometry>
  </collision>
</link>

<link name="BR_femur_servo1">
  <inertial>
    <origin xyz="-0.2450089388751371 0.2445261424038342 -0.016815356524645608" rpy="0 0 0"/>
    <mass value="0.04604548230153534"/>
    <inertia ixx="7.68790629804934e-06" iyy="8.016869330744556e-06" izz="1.2595635604749182e-05" ixy="-2.701509660158613e-08" iyz="3.729655473350135e-17" ixz="2.506024901482995e-15"/>
  </inertial>
  <visual>
    <origin xyz="-0.064 0.0357 -0.186131" rpy="0 0 0"/>
    <geometry>
      <mesh filename="meshes/BR_femur_servo1.stl" scale="0.001 0.001 0.001"/>
    </geometry>
    <material name="silver"/>
    <material/>
  </visual>
  <collision>
    <origin xyz="-0.064 0.0357 -0.186131" rpy="0 0 0"/>
    <geometry>
      <mesh filename="meshes/BR_femur_servo1.stl" scale="0.001 0.001 0.001"/>
    </geometry>
  </collision>
</link>

<link name="BR_tibia_servo1">
  <inertial>
    <origin xyz="-0.2937375867529123 0.24452614240383413 -0.0068153565248151304" rpy="0 0 0"/>
    <mass value="0.04604548230153534"/>
    <inertia ixx="7.68790629804934e-06" iyy="8.016869330744556e-06" izz="1.2595635604749616e-05" ixy="2.701509660071877e-08" iyz="-3.729655473350135e-17" ixz="2.506241741917492e-15"/>
  </inertial>
  <visual>
    <origin xyz="-0.113 0.0357 -0.155631" rpy="0 0 0"/>
    <geometry>
      <mesh filename="meshes/BR_tibia_servo1.stl" scale="0.001 0.001 0.001"/>
    </geometry>
    <material name="silver"/>
    <material/>
  </visual>
  <collision>
    <origin xyz="-0.113 0.0357 -0.155631" rpy="0 0 0"/>
    <geometry>
      <mesh filename="meshes/BR_tibia_servo1.stl" scale="0.001 0.001 0.001"/>
    </geometry>
  </collision>
</link>

<link name="BR_femur_servo_arm1">
  <inertial>
    <origin xyz="0.006439894030634885 0.0033827214696438568 -0.004527843864061437" rpy="0 0 0"/>
    <mass value="0.0032701003729527518"/>
    <inertia ixx="1.4142465806245546e-07" iyy="3.5431642633773175e-07" izz="2.3003667960264963e-07" ixy="-2.0774468161900185e-09" iyz="1.4060869729290958e-09" ixz="1.3359878788218632e-07"/>
  </inertial>
  <visual>
    <origin xyz="0.171173 -0.230396 -0.169316" rpy="0 0 0"/>
    <geometry>
      <mesh filename="meshes/BR_femur_servo_arm1.stl" scale="0.001 0.001 0.001"/>
    </geometry>
    <material name="silver"/>
    <material/>
  </visual>
  <collision>
    <origin xyz="0.171173 -0.230396 -0.169316" rpy="0 0 0"/>
    <geometry>
      <mesh filename="meshes/BR_femur_servo_arm1.stl" scale="0.001 0.001 0.001"/>
    </geometry>
  </collision>
</link>

<link name="BR_leg_knee_up1">
  <inertial>
    <origin xyz="0.038908864022376866 0.008191177893324686 -0.026682944621231275" rpy="0 0 0"/>
    <mass value="0.016745594670500637"/>
    <inertia ixx="5.486008768117818e-06" iyy="1.5337512544609652e-05" izz="1.0870969302652963e-05" ixy="2.4256040583080576e-07" iyz="-1.7122387702237125e-07" ixz="6.875967737337413e-06"/>
  </inertial>
  <visual>
    <origin xyz="0.171173 -0.236396 -0.169316" rpy="0 0 0"/>
    <geometry>
      <mesh filename="meshes/BR_leg_knee_up1.stl" scale="0.001 0.001 0.001"/>
    </geometry>
    <material name="silver"/>
    <material/>
  </visual>
  <collision>
    <origin xyz="0.171173 -0.236396 -0.169316" rpy="0 0 0"/>
    <geometry>
      <mesh filename="meshes/BR_leg_knee_up1.stl" scale="0.001 0.001 0.001"/>
    </geometry>
  </collision>
</link>

<link name="BR_leg_ankle1">
  <inertial>
    <origin xyz="-0.0363314094951432 -0.006599466184680103 -0.03077805670196493" rpy="0 0 0"/>
    <mass value="0.022209898104400553"/>
    <inertia ixx="8.758836859266332e-06" iyy="1.814216094624848e-05" izz="1.2497611473033868e-05" ixy="7.259261063357475e-11" iyz="2.173650678395124e-10" ixz="-8.477746015364887e-06"/>
  </inertial>
  <visual>
    <origin xyz="0.097532 -0.249396 -0.115164" rpy="0 0 0"/>
    <geometry>
      <mesh filename="meshes/BR_leg_ankle1.stl" scale="0.001 0.001 0.001"/>
    </geometry>
    <material name="silver"/>
    <material/>
  </visual>
  <collision>
    <origin xyz="0.097532 -0.249396 -0.115164" rpy="0 0 0"/>
    <geometry>
      <mesh filename="meshes/BR_leg_ankle1.stl" scale="0.001 0.001 0.001"/>
    </geometry>
  </collision>
</link>

<link name="BR_leg_foot1Component161">
  <inertial>
    <origin xyz="-0.00014618644725039598 4.77648235721051e-05 0.04182793854814934" rpy="0 0 0"/>
    <mass value="0.05068893861578388"/>
    <inertia ixx="2.8920105002671042e-05" iyy="2.8848623228453808e-05" izz="4.035863536627077e-06" ixy="-1.684308197731285e-08" iyz="8.205216364643927e-08" ixz="-2.112921897726638e-07"/>
  </inertial>
  <visual>
    <origin xyz="0.165354 -0.24281 -0.056133" rpy="0 0 0"/>
    <geometry>
      <mesh filename="meshes/BR_leg_foot1Component161.stl" scale="0.001 0.001 0.001"/>
    </geometry>
    <material name="silver"/>
    <material/>
  </visual>
  <collision>
    <origin xyz="0.165354 -0.24281 -0.056133" rpy="0 0 0"/>
    <geometry>
      <mesh filename="meshes/BR_leg_foot1Component161.stl" scale="0.001 0.001 0.001"/>
    </geometry>
  </collision>
</link>

<link name="BR_shoulder_servo_arm1">
  <inertial>
    <origin xyz="0.0033822602874598595 1.4977990047959633e-05 0.007872322613020066" rpy="0 0 0"/>
    <mass value="0.003270096931145701"/>
    <inertia ixx="3.543162629485728e-07" iyy="3.264258884250003e-07" izz="4.5035220720658024e-08" ixy="3.9807266041276676e-11" iyz="-4.059464588535445e-09" ixz="-2.5081215526742814e-09"/>
  </inertial>
  <visual>
    <origin xyz="0.040546 -0.211596 -0.150395" rpy="0 0 0"/>
    <geometry>
      <mesh filename="meshes/BR_shoulder_servo_arm1.stl" scale="0.001 0.001 0.001"/>
    </geometry>
    <material name="silver"/>
    <material/>
  </visual>
  <collision>
    <origin xyz="0.040546 -0.211596 -0.150395" rpy="0 0 0"/>
    <geometry>
      <mesh filename="meshes/BR_shoulder_servo_arm1.stl" scale="0.001 0.001 0.001"/>
    </geometry>
  </collision>
</link>

<link name="BR_leg_hip_servo_holder1">
  <inertial>
    <origin xyz="0.029061726116576085 -0.000733908796302668 0.015154064659330752" rpy="0 0 0"/>
    <mass value="0.03470303413377986"/>
    <inertia ixx="1.0251432959789298e-05" iyy="2.859304047357668e-05" izz="2.33429415732666e-05" ixy="9.729946632087077e-08" iyz="-1.8050301079123796e-07" ixz="-1.984837802496046e-06"/>
  </inertial>
  <visual>
    <origin xyz="0.034546 -0.211596 -0.150395" rpy="0 0 0"/>
    <geometry>
      <mesh filename="meshes/BR_leg_hip_servo_holder1.stl" scale="0.001 0.001 0.001"/>
    </geometry>
    <material name="silver"/>
    <material/>
  </visual>
  <collision>
    <origin xyz="0.034546 -0.211596 -0.150395" rpy="0 0 0"/>
    <geometry>
      <mesh filename="meshes/BR_leg_hip_servo_holder1.stl" scale="0.001 0.001 0.001"/>
    </geometry>
  </collision>
</link>

<link name="BR_leg_foot2Component161">
  <inertial>
    <origin xyz="0.1808118094298725 0.002247765240831784 0.03596958586437543" rpy="0 0 0"/>
    <mass value="0.05068893861578388"/>
    <inertia ixx="2.87677717351535e-05" iyy="2.8848623228453104e-05" izz="4.188196804144617e-06" ixy="-2.3930306231447016e-08" iyz="8.027195907154075e-08" ixz="1.9524694049635185e-06"/>
  </inertial>
  <visual>
    <origin xyz="0.165354 -0.24281 -0.056133" rpy="0 0 0"/>
    <geometry>
      <mesh filename="meshes/BR_leg_foot2Component161.stl" scale="0.001 0.001 0.001"/>
    </geometry>
    <material name="silver"/>
    <material/>
  </visual>
  <collision>
    <origin xyz="0.165354 -0.24281 -0.056133" rpy="0 0 0"/>
    <geometry>
      <mesh filename="meshes/BR_leg_foot2Component161.stl" scale="0.001 0.001 0.001"/>
    </geometry>
  </collision>
</link>

<link name="BR_leg_ankle2">
  <inertial>
    <origin xyz="-0.03240366231190828 0.25079653423257986 -0.27124042563700634" rpy="0 0 0"/>
    <mass value="0.022209898104400553"/>
    <inertia ixx="1.0259382199239147e-05" iyy="1.8142160946248045e-05" izz="1.0997066133059535e-05" ixy="5.3371759919582096e-11" iyz="2.2286479102072085e-10" ixz="-8.673565703193548e-06"/>
  </inertial>
  <visual>
    <origin xyz="-0.080561 0.0058 -0.352577" rpy="0 0 0"/>
    <geometry>
      <mesh filename="meshes/BR_leg_ankle2.stl" scale="0.001 0.001 0.001"/>
    </geometry>
    <material name="silver"/>
    <material/>
  </visual>
  <collision>
    <origin xyz="-0.080561 0.0058 -0.352577" rpy="0 0 0"/>
    <geometry>
      <mesh filename="meshes/BR_leg_ankle2.stl" scale="0.001 0.001 0.001"/>
    </geometry>
  </collision>
</link>

<link name="BR_leg_knee_up2">
  <inertial>
    <origin xyz="0.21810886581059247 0.010191178310584054 -0.02668294462123158" rpy="0 0 0"/>
    <mass value="0.016745594670500637"/>
    <inertia ixx="5.4860087681186855e-06" iyy="1.533751254460846e-05" izz="1.0870969302651011e-05" ixy="2.425604058309955e-07" iyz="-1.7122387702215441e-07" ixz="6.875967737337508e-06"/>
  </inertial>
  <visual>
    <origin xyz="0.171173 -0.236396 -0.169316" rpy="0 0 0"/>
    <geometry>
      <mesh filename="meshes/BR_leg_knee_up2.stl" scale="0.001 0.001 0.001"/>
    </geometry>
    <material name="silver"/>
    <material/>
  </visual>
  <collision>
    <origin xyz="0.171173 -0.236396 -0.169316" rpy="0 0 0"/>
    <geometry>
      <mesh filename="meshes/BR_leg_knee_up2.stl" scale="0.001 0.001 0.001"/>
    </geometry>
  </collision>
</link>

<link name="BR_femur_servo_arm2">
  <inertial>
    <origin xyz="0.18563989581884985 0.005382721886902836 -0.004527843864061909" rpy="0 0 0"/>
    <mass value="0.0032701003729527518"/>
    <inertia ixx="1.4142465806250967e-07" iyy="3.543164263377724e-07" izz="2.3003667960259542e-07" ixy="-2.0774468162137354e-09" iyz="1.4060869729290958e-09" ixz="1.3359878788218632e-07"/>
  </inertial>
  <visual>
    <origin xyz="0.171173 -0.230396 -0.169316" rpy="0 0 0"/>
    <geometry>
      <mesh filename="meshes/BR_femur_servo_arm2.stl" scale="0.001 0.001 0.001"/>
    </geometry>
    <material name="silver"/>
    <material/>
  </visual>
  <collision>
    <origin xyz="0.171173 -0.230396 -0.169316" rpy="0 0 0"/>
    <geometry>
      <mesh filename="meshes/BR_femur_servo_arm2.stl" scale="0.001 0.001 0.001"/>
    </geometry>
  </collision>
</link>

<link name="BR_femur_servo2">
  <inertial>
    <origin xyz="0.06553806291307783 0.24652614282109317 0.33181564347535397" rpy="0 0 0"/>
    <mass value="0.04604548230153534"/>
    <inertia ixx="7.68790629804934e-06" iyy="8.016869330743472e-06" izz="1.2595635604748315e-05" ixy="-2.7015096600705216e-08" iyz="3.7730235602495554e-17" ixz="2.5059774676379487e-15"/>
  </inertial>
  <visual>
    <origin xyz="0.067347 0.0357 0.1625" rpy="0 0 0"/>
    <geometry>
      <mesh filename="meshes/BR_femur_servo2.stl" scale="0.001 0.001 0.001"/>
    </geometry>
    <material name="silver"/>
    <material/>
  </visual>
  <collision>
    <origin xyz="0.067347 0.0357 0.1625" rpy="0 0 0"/>
    <geometry>
      <mesh filename="meshes/BR_femur_servo2.stl" scale="0.001 0.001 0.001"/>
    </geometry>
  </collision>
</link>

<link name="BR_tibia_servo2">
  <inertial>
    <origin xyz="0.06520941503530256 0.24652614282109309 0.2908156434751842" rpy="0 0 0"/>
    <mass value="0.04604548230153534"/>
    <inertia ixx="7.687906298048906e-06" iyy="8.016869330743906e-06" izz="1.2595635604748748e-05" ixy="2.7015096600695052e-08" iyz="-3.7513395167998453e-17" ixz="2.5059503625836366e-15"/>
  </inertial>
  <visual>
    <origin xyz="0.067347 0.0357 0.142" rpy="0 0 0"/>
    <geometry>
      <mesh filename="meshes/BR_tibia_servo2.stl" scale="0.001 0.001 0.001"/>
    </geometry>
    <material name="silver"/>
    <material/>
  </visual>
  <collision>
    <origin xyz="0.067347 0.0357 0.142" rpy="0 0 0"/>
    <geometry>
      <mesh filename="meshes/BR_tibia_servo2.stl" scale="0.001 0.001 0.001"/>
    </geometry>
  </collision>
</link>

<link name="FR_shoulder_servo1">
  <inertial>
    <origin xyz="0.01096979865336728 0.005000202977215817 -0.024964333349484447" rpy="0 0 0"/>
    <mass value="0.04604548230153534"/>
    <inertia ixx="8.016869330744556e-06" iyy="1.2595635604748532e-05" izz="7.687906298049774e-06" ixy="-3.729655473350135e-17" iyz="-2.506024901482995e-15" ixz="-2.701509660082719e-08"/>
  </inertial>
  <visual>
    <origin xyz="0.1314 -0.206596 -0.185195" rpy="0 0 0"/>
    <geometry>
      <mesh filename="meshes/FR_shoulder_servo1.stl" scale="0.001 0.001 0.001"/>
    </geometry>
    <material name="silver"/>
    <material/>
  </visual>
  <collision>
    <origin xyz="0.1314 -0.206596 -0.185195" rpy="0 0 0"/>
    <geometry>
      <mesh filename="meshes/FR_shoulder_servo1.stl" scale="0.001 0.001 0.001"/>
    </geometry>
  </collision>
</link>

<link name="BR_shoulder_servo1">
  <inertial>
    <origin xyz="-0.010970322493202428 0.005000203394470382 -0.024964333349484363" rpy="0 0 0"/>
    <mass value="0.04604548230153534"/>
    <inertia ixx="8.016869330742821e-06" iyy="1.2595635604748315e-05" izz="7.68790629804934e-06" ixy="3.729655473350135e-17" iyz="-2.5053743801795036e-15" ixz="2.7015096600501928e-08"/>
  </inertial>
  <visual>
    <origin xyz="0.051146 -0.206596 -0.185195" rpy="0 0 0"/>
    <geometry>
      <mesh filename="meshes/BR_shoulder_servo1.stl" scale="0.001 0.001 0.001"/>
    </geometry>
    <material name="silver"/>
    <material/>
  </visual>
  <collision>
    <origin xyz="0.051146 -0.206596 -0.185195" rpy="0 0 0"/>
    <geometry>
      <mesh filename="meshes/BR_shoulder_servo1.stl" scale="0.001 0.001 0.001"/>
    </geometry>
  </collision>
</link>

<link name="BL_leg_foot1Component491">
  <inertial>
    <origin xyz="-0.0001463774728331091 -4.7584773372189026e-05 0.04182786059321382" rpy="0 0 0"/>
    <mass value="0.0506890267071983"/>
    <inertia ixx="2.892028258220556e-05" iyy="2.8848793857976255e-05" izz="4.035865445157485e-06" ixy="1.684200289289988e-08" iyz="-8.20442123170657e-08" ixz="-2.11299069876247e-07"/>
  </inertial>
  <visual>
    <origin xyz="0.164807 -0.075196 -0.056133" rpy="0 0 0"/>
    <geometry>
      <mesh filename="meshes/BL_leg_foot1Component491.stl" scale="0.001 0.001 0.001"/>
    </geometry>
    <material name="silver"/>
    <material/>
  </visual>
  <collision>
    <origin xyz="0.164807 -0.075196 -0.056133" rpy="0 0 0"/>
    <geometry>
      <mesh filename="meshes/BL_leg_foot1Component491.stl" scale="0.001 0.001 0.001"/>
    </geometry>
  </collision>
</link>

<link name="BL_leg_ankle1">
  <inertial>
    <origin xyz="-0.036331464654955584 -0.006600125695097145 -0.030778106086590526" rpy="0 0 0"/>
    <mass value="0.022209946665644437"/>
    <inertia ixx="8.758864927658453e-06" iyy="1.814221815535442e-05" izz="1.2497646484326127e-05" ixy="-7.136090809521829e-11" iyz="-2.16161878164884e-10" ixz="-8.477773878468693e-06"/>
  </inertial>
  <visual>
    <origin xyz="0.096932 -0.081796 -0.115164" rpy="0 0 0"/>
    <geometry>
      <mesh filename="meshes/BL_leg_ankle1.stl" scale="0.001 0.001 0.001"/>
    </geometry>
    <material name="silver"/>
    <material/>
  </visual>
  <collision>
    <origin xyz="0.096932 -0.081796 -0.115164" rpy="0 0 0"/>
    <geometry>
      <mesh filename="meshes/BL_leg_ankle1.stl" scale="0.001 0.001 0.001"/>
    </geometry>
  </collision>
</link>

<link name="BL_leg_knee_up1">
  <inertial>
    <origin xyz="0.03890886157870843 -0.008190773772252954 -0.026682940385714116" rpy="0 0 0"/>
    <mass value="0.016745581865497832"/>
    <inertia ixx="5.486005287794096e-06" iyy="1.5337505884211507e-05" izz="1.0870965100775239e-05" ixy="-2.4256059980427803e-07" iyz="1.712239324825921e-07" ixz="6.875964549787146e-06"/>
  </inertial>
  <visual>
    <origin xyz="0.170573 -0.081796 -0.169316" rpy="0 0 0"/>
    <geometry>
      <mesh filename="meshes/BL_leg_knee_up1.stl" scale="0.001 0.001 0.001"/>
    </geometry>
    <material name="silver"/>
    <material/>
  </visual>
  <collision>
    <origin xyz="0.170573 -0.081796 -0.169316" rpy="0 0 0"/>
    <geometry>
      <mesh filename="meshes/BL_leg_knee_up1.stl" scale="0.001 0.001 0.001"/>
    </geometry>
  </collision>
</link>

<link name="BL_tibia_servo1">
  <inertial>
    <origin xyz="0.006439899696519369 -0.0033823188134061988 -0.0045278433128485285" rpy="0 0 0"/>
    <mass value="0.003270096931145703"/>
    <inertia ixx="1.4142456523732094e-07" iyy="3.5431626294851856e-07" izz="2.3003654389975865e-07" ixy="2.0773653985428717e-09" iyz="-1.4059912128389714e-09" ixz="1.3359878566031726e-07"/>
  </inertial>
  <visual>
    <origin xyz="0.170573 -0.087796 -0.169316" rpy="0 0 0"/>
    <geometry>
      <mesh filename="meshes/BL_tibia_servo1.stl" scale="0.001 0.001 0.001"/>
    </geometry>
    <material name="silver"/>
    <material/>
  </visual>
  <collision>
    <origin xyz="0.170573 -0.087796 -0.169316" rpy="0 0 0"/>
    <geometry>
      <mesh filename="meshes/BL_tibia_servo1.stl" scale="0.001 0.001 0.001"/>
    </geometry>
  </collision>
</link>

<link name="BL_femur_servo1">
  <inertial>
    <origin xyz="0.024964061124866765 0.010970263967655852 -0.005000356524645505" rpy="0 0 0"/>
    <mass value="0.04604548230153534"/>
    <inertia ixx="7.687906298049123e-06" iyy="8.016869330744122e-06" izz="1.2595635604749182e-05" ixy="2.7015096600501928e-08" iyz="-3.74049749507499e-17" ixz="2.505808061048498e-15"/>
  </inertial>
  <visual>
    <origin xyz="0.205373 -0.098396 -0.174316" rpy="0 0 0"/>
    <geometry>
      <mesh filename="meshes/BL_femur_servo1.stl" scale="0.001 0.001 0.001"/>
    </geometry>
    <material name="silver"/>
    <material/>
  </visual>
  <collision>
    <origin xyz="0.205373 -0.098396 -0.174316" rpy="0 0 0"/>
    <geometry>
      <mesh filename="meshes/BL_femur_servo1.stl" scale="0.001 0.001 0.001"/>
    </geometry>
  </collision>
</link>

<link name="FL_tibia_servo1">
  <inertial>
    <origin xyz="0.024635413247091176 0.010970263967655894 -0.005000356524815286" rpy="0 0 0"/>
    <mass value="0.04604548230153534"/>
    <inertia ixx="7.687906298048906e-06" iyy="8.016869330743689e-06" izz="1.2595635604748748e-05" ixy="-2.701509660093561e-08" iyz="3.7621815385247004e-17" ixz="2.506024901482995e-15"/>
  </inertial>
  <visual>
    <origin xyz="0.205373 -0.098396 -0.153816" rpy="0 0 0"/>
    <geometry>
      <mesh filename="meshes/FL_tibia_servo1.stl" scale="0.001 0.001 0.001"/>
    </geometry>
    <material name="silver"/>
    <material/>
  </visual>
  <collision>
    <origin xyz="0.205373 -0.098396 -0.153816" rpy="0 0 0"/>
    <geometry>
      <mesh filename="meshes/FL_tibia_servo1.stl" scale="0.001 0.001 0.001"/>
    </geometry>
  </collision>
</link>

<link name="FL_leg_hip_servo_holder1">
  <inertial>
    <origin xyz="-0.029062249956406966 0.0007343155850514926 0.015154064659331196" rpy="0 0 0"/>
    <mass value="0.03470303413377986"/>
    <inertia ixx="1.0251432959791033e-05" iyy="2.859304047357755e-05" izz="2.3342941573267035e-05" ixy="9.7299466320349e-08" iyz="1.8050301079123796e-07" ixz="1.9848378024968794e-06"/>
  </inertial>
  <visual>
    <origin xyz="0.148 -0.108596 -0.150395" rpy="0 0 0"/>
    <geometry>
      <mesh filename="meshes/FL_leg_hip_servo_holder1.stl" scale="0.001 0.001 0.001"/>
    </geometry>
    <material name="silver"/>
    <material/>
  </visual>
  <collision>
    <origin xyz="0.148 -0.108596 -0.150395" rpy="0 0 0"/>
    <geometry>
      <mesh filename="meshes/FL_leg_hip_servo_holder1.stl" scale="0.001 0.001 0.001"/>
    </geometry>
  </collision>
</link>

<link name="FL_shoulder_servo_arm1">
  <inertial>
    <origin xyz="-0.0033827841272915937 -1.4571201298954617e-05 0.007872322613020455" rpy="0 0 0"/>
    <mass value="0.003270096931145701"/>
    <inertia ixx="3.543162629485321e-07" iyy="3.2642588842498677e-07" izz="4.5035220720603814e-08" ixy="3.9807266024336017e-11" iyz="4.05946458850834e-09" ixz="2.5081215526776696e-09"/>
  </inertial>
  <visual>
    <origin xyz="0.142 -0.108596 -0.150395" rpy="0 0 0"/>
    <geometry>
      <mesh filename="meshes/FL_shoulder_servo_arm1.stl" scale="0.001 0.001 0.001"/>
    </geometry>
    <material name="silver"/>
    <material/>
  </visual>
  <collision>
    <origin xyz="0.142 -0.108596 -0.150395" rpy="0 0 0"/>
    <geometry>
      <mesh filename="meshes/FL_shoulder_servo_arm1.stl" scale="0.001 0.001 0.001"/>
    </geometry>
  </collision>
</link>

<link name="FL_shoulder_servo1">
  <inertial>
    <origin xyz="0.010969798653371027 -0.0049997966057213905 -0.024964333349484585" rpy="0 0 0"/>
    <mass value="0.04604548230153534"/>
    <inertia ixx="8.016869330743472e-06" iyy="1.2595635604748748e-05" izz="7.68790629804934e-06" ixy="3.707971429900425e-17" iyz="2.5061333217002435e-15" ixz="-2.7015096600501928e-08"/>
  </inertial>
  <visual>
    <origin xyz="0.1314 -0.113596 -0.185195" rpy="0 0 0"/>
    <geometry>
      <mesh filename="meshes/FL_shoulder_servo1.stl" scale="0.001 0.001 0.001"/>
    </geometry>
    <material name="silver"/>
    <material/>
  </visual>
  <collision>
    <origin xyz="0.1314 -0.113596 -0.185195" rpy="0 0 0"/>
    <geometry>
      <mesh filename="meshes/FL_shoulder_servo1.stl" scale="0.001 0.001 0.001"/>
    </geometry>
  </collision>
</link>

<link name="BL_leg_foot2Component491">
  <inertial>
    <origin xyz="-0.27217327285439336 -0.08954435376429724 0.09255661794334877" rpy="0 0 0"/>
    <mass value="0.0506890267071983"/>
    <inertia ixx="2.876794917498586e-05" iyy="2.88487938579762e-05" izz="4.18819885237762e-06" ixy="2.392853824962894e-08" iyz="-8.026413204806045e-08" ixz="1.9524778818577946e-06"/>
  </inertial>
  <visual>
    <origin xyz="-0.287631 -0.164679 0.000485" rpy="0 0 0"/>
    <geometry>
      <mesh filename="meshes/BL_leg_foot2Component491.stl" scale="0.001 0.001 0.001"/>
    </geometry>
    <material name="silver"/>
    <material/>
  </visual>
  <collision>
    <origin xyz="-0.287631 -0.164679 0.000485" rpy="0 0 0"/>
    <geometry>
      <mesh filename="meshes/BL_leg_foot2Component491.stl" scale="0.001 0.001 0.001"/>
    </geometry>
  </collision>
</link>

<link name="BL_leg_ankle2">
  <inertial>
    <origin xyz="0.14508920253954982 -0.006600125277838806 -0.03385836950361426" rpy="0 0 0"/>
    <mass value="0.022209946665644437"/>
    <inertia ixx="1.025941515874813e-05" iyy="1.8142218155354123e-05" izz="1.0997096253236423e-05" ixy="-5.224960893633612e-11" iyz="-2.215588296053221e-10" ixz="-8.673593745805292e-06"/>
  </inertial>
  <visual>
    <origin xyz="0.096932 -0.081796 -0.115164" rpy="0 0 0"/>
    <geometry>
      <mesh filename="meshes/BL_leg_ankle2.stl" scale="0.001 0.001 0.001"/>
    </geometry>
    <material name="silver"/>
    <material/>
  </visual>
  <collision>
    <origin xyz="0.096932 -0.081796 -0.115164" rpy="0 0 0"/>
    <geometry>
      <mesh filename="meshes/BL_leg_ankle2.stl" scale="0.001 0.001 0.001"/>
    </geometry>
  </collision>
</link>

<link name="BL_leg_knee_up2">
  <inertial>
    <origin xyz="0.21750877886414094 -0.008190773354994574 -0.026713830248124792" rpy="0 0 0"/>
    <mass value="0.016745581865497832"/>
    <inertia ixx="5.486005287793987e-06" iyy="1.5337505884211074e-05" izz="1.0870965100775375e-05" ixy="-2.4256059980387146e-07" iyz="1.7122393248232104e-07" ixz="6.875964549787065e-06"/>
  </inertial>
  <visual>
    <origin xyz="0.170573 -0.081796 -0.169316" rpy="0 0 0"/>
    <geometry>
      <mesh filename="meshes/BL_leg_knee_up2.stl" scale="0.001 0.001 0.001"/>
    </geometry>
    <material name="silver"/>
    <material/>
  </visual>
  <collision>
    <origin xyz="0.170573 -0.081796 -0.169316" rpy="0 0 0"/>
    <geometry>
      <mesh filename="meshes/BL_leg_knee_up2.stl" scale="0.001 0.001 0.001"/>
    </geometry>
  </collision>
</link>

<link name="BL_tibia_servo2">
  <inertial>
    <origin xyz="0.18503981698195146 -0.0033823183961466247 -0.004558733175259594" rpy="0 0 0"/>
    <mass value="0.003270096931145703"/>
    <inertia ixx="1.4142456523729384e-07" iyy="3.543162629485321e-07" izz="2.300365438997417e-07" ixy="2.0773653985564243e-09" iyz="-1.4059912128321951e-09" ixz="1.3359878566029523e-07"/>
  </inertial>
  <visual>
    <origin xyz="0.170573 -0.087796 -0.169316" rpy="0 0 0"/>
    <geometry>
      <mesh filename="meshes/BL_tibia_servo2.stl" scale="0.001 0.001 0.001"/>
    </geometry>
    <material name="silver"/>
    <material/>
  </visual>
  <collision>
    <origin xyz="0.170573 -0.087796 -0.169316" rpy="0 0 0"/>
    <geometry>
      <mesh filename="meshes/BL_tibia_servo2.stl" scale="0.001 0.001 0.001"/>
    </geometry>
  </collision>
</link>

<link name="BL_femur_servo2">
  <inertial>
    <origin xyz="0.06553797841029983 -0.12312573561508398 -0.016785246387056585" rpy="0 0 0"/>
    <mass value="0.04604548230153534"/>
    <inertia ixx="7.687906298049557e-06" iyy="8.016869330743689e-06" izz="1.2595635604749399e-05" ixy="2.7015096600674723e-08" iyz="-3.7513395167998453e-17" ixz="2.505952056649531e-15"/>
  </inertial>
  <visual>
    <origin xyz="0.067347 -0.232492 -0.18607" rpy="0 0 0"/>
    <geometry>
      <mesh filename="meshes/BL_femur_servo2.stl" scale="0.001 0.001 0.001"/>
    </geometry>
    <material name="silver"/>
    <material/>
  </visual>
  <collision>
    <origin xyz="0.067347 -0.232492 -0.18607" rpy="0 0 0"/>
    <geometry>
      <mesh filename="meshes/BL_femur_servo2.stl" scale="0.001 0.001 0.001"/>
    </geometry>
  </collision>
</link>

<link name="FL_tibia_servo2">
  <inertial>
    <origin xyz="0.06520933053252455 -0.12312573561508398 -0.016785246387226144" rpy="0 0 0"/>
    <mass value="0.04604548230153534"/>
    <inertia ixx="7.687906298049123e-06" iyy="8.016869330743689e-06" izz="1.259563560474929e-05" ixy="-2.7015096600657782e-08" iyz="3.74049749507499e-17" ixz="2.5059266456611134e-15"/>
  </inertial>
  <visual>
    <origin xyz="0.067347 -0.232492 -0.16557" rpy="0 0 0"/>
    <geometry>
      <mesh filename="meshes/FL_tibia_servo2.stl" scale="0.001 0.001 0.001"/>
    </geometry>
    <material name="silver"/>
    <material/>
  </visual>
  <collision>
    <origin xyz="0.067347 -0.232492 -0.16557" rpy="0 0 0"/>
    <geometry>
      <mesh filename="meshes/FL_tibia_servo2.stl" scale="0.001 0.001 0.001"/>
    </geometry>
  </collision>
</link>

<link name="BL_leg_hip_servo_holder1">
  <inertial>
    <origin xyz="0.029061641613797817 0.0007343160023104561 0.015154174796920411" rpy="0 0 0"/>
    <mass value="0.03470303413377985"/>
    <inertia ixx="1.0251432959789081e-05" iyy="2.8593040473575923e-05" izz="2.334294157326633e-05" ixy="-9.729946632224635e-08" iyz="1.8050301079102112e-07" ixz="-1.9848378024960155e-06"/>
  </inertial>
  <visual>
    <origin xyz="0.034546 -0.108596 -0.150364" rpy="0 0 0"/>
    <geometry>
      <mesh filename="meshes/BL_leg_hip_servo_holder1.stl" scale="0.001 0.001 0.001"/>
    </geometry>
    <material name="silver"/>
    <material/>
  </visual>
  <collision>
    <origin xyz="0.034546 -0.108596 -0.150364" rpy="0 0 0"/>
    <geometry>
      <mesh filename="meshes/BL_leg_hip_servo_holder1.stl" scale="0.001 0.001 0.001"/>
    </geometry>
  </collision>
</link>

<link name="BL_shoulder_servo_arm1">
  <inertial>
    <origin xyz="0.003382172069066866 -1.4574485384305502e-05 0.007872428425555855" rpy="0 0 0"/>
    <mass value="0.0032701003729527518"/>
    <inertia ixx="3.5431642633773175e-07" iyy="3.2642601211326427e-07" izz="4.503532556809708e-08" ixy="-3.9775523183422723e-11" iyz="4.059445202499157e-09" ixz="-2.5082431811607794e-09"/>
  </inertial>
  <visual>
    <origin xyz="0.040546 -0.108596 -0.150364" rpy="0 0 0"/>
    <geometry>
      <mesh filename="meshes/BL_shoulder_servo_arm1.stl" scale="0.001 0.001 0.001"/>
    </geometry>
    <material name="silver"/>
    <material/>
  </visual>
  <collision>
    <origin xyz="0.040546 -0.108596 -0.150364" rpy="0 0 0"/>
    <geometry>
      <mesh filename="meshes/BL_shoulder_servo_arm1.stl" scale="0.001 0.001 0.001"/>
    </geometry>
  </collision>
</link>

<link name="BL_shoulder_servo1">
  <inertial>
    <origin xyz="-0.010970406995980411 -0.004999796188466868 -0.024964223211895148" rpy="0 0 0"/>
    <mass value="0.04604548230153534"/>
    <inertia ixx="8.016869330743472e-06" iyy="1.2595635604748748e-05" izz="7.687906298048798e-06" ixy="-3.756760527662273e-17" iyz="2.506024901482995e-15" ixz="2.701509660071877e-08"/>
  </inertial>
  <visual>
    <origin xyz="0.051146 -0.113596 -0.185164" rpy="0 0 0"/>
    <geometry>
      <mesh filename="meshes/BL_shoulder_servo1.stl" scale="0.001 0.001 0.001"/>
    </geometry>
    <material name="silver"/>
    <material/>
  </visual>
  <collision>
    <origin xyz="0.051146 -0.113596 -0.185164" rpy="0 0 0"/>
    <geometry>
      <mesh filename="meshes/BL_shoulder_servo1.stl" scale="0.001 0.001 0.001"/>
    </geometry>
  </collision>
</link>

<joint name="Revolute_23" type="continuous">
  <origin xyz="-0.0106 0.005 -0.0348" rpy="0 0 0"/>
  <parent link="FR_shoulder_servo1"/>
  <child link="FR_shoulder_servo_arm1"/>
  <axis xyz="1.0 0.0 -0.0"/>
</joint>
<transmission name="Revolute_23_tran">
  <type>transmission_interface/SimpleTransmission</type>
  <joint name="Revolute_23">
    <hardwareInterface>PositionJointInterface</hardwareInterface>
  </joint>
  <actuator name="Revolute_23_actr">
    <hardwareInterface>PositionJointInterface</hardwareInterface>
    <mechanicalReduction>1</mechanicalReduction>
  </actuator>
</transmission>

<joint name="Rigid_24" type="fixed">
  <origin xyz="-0.006 0.0 0.0" rpy="0 0 0"/>
  <parent link="FR_shoulder_servo_arm1"/>
  <child link="FR_leg_hip_servo_holder1"/>
</joint>

<joint name="Rigid_25" type="fixed">
  <origin xyz="0.212 -0.247296 0.035736" rpy="0 0 0"/>
  <parent link="FR_leg_hip_servo_holder1"/>
  <child link="BR_femur_servo1"/>
</joint>

<joint name="Rigid_26" type="fixed">
  <origin xyz="0.261 -0.247296 0.005236" rpy="0 0 0"/>
  <parent link="FR_leg_hip_servo_holder1"/>
  <child link="BR_tibia_servo1"/>
</joint>

<joint name="Revolute_40" type="continuous">
  <origin xyz="-0.235173 0.266096 -0.016815" rpy="0 0 0"/>
  <parent link="BR_femur_servo1"/>
  <child link="BR_femur_servo_arm1"/>
  <axis xyz="0.0 -1.0 0.0"/>
</joint>
<transmission name="Revolute_40_tran">
  <type>transmission_interface/SimpleTransmission</type>
  <joint name="Revolute_40">
    <hardwareInterface>PositionJointInterface</hardwareInterface>
  </joint>
  <actuator name="Revolute_40_actr">
    <hardwareInterface>PositionJointInterface</hardwareInterface>
    <mechanicalReduction>1</mechanicalReduction>
  </actuator>
</transmission>

<joint name="Rigid_41" type="fixed">
  <origin xyz="0.0 0.006 0.0" rpy="0 0 0"/>
  <parent link="BR_femur_servo_arm1"/>
  <child link="BR_leg_knee_up1"/>
</joint>

<joint name="Revolute_42" type="continuous">
  <origin xyz="0.073641 0.013 -0.054152" rpy="0 0 0"/>
  <parent link="BR_leg_knee_up1"/>
  <child link="BR_leg_ankle1"/>
  <axis xyz="0.0 -1.0 0.0"/>
</joint>
<transmission name="Revolute_42_tran">
  <type>transmission_interface/SimpleTransmission</type>
  <joint name="Revolute_42">
    <hardwareInterface>PositionJointInterface</hardwareInterface>
  </joint>
  <actuator name="Revolute_42_actr">
    <hardwareInterface>PositionJointInterface</hardwareInterface>
    <mechanicalReduction>1</mechanicalReduction>
  </actuator>
</transmission>

<joint name="Rigid_43" type="fixed">
  <origin xyz="-0.067822 -0.006586 -0.059031" rpy="0 0 0"/>
  <parent link="BR_leg_ankle1"/>
  <child link="BR_leg_foot1Component161"/>
</joint>

<joint name="Revolute_45" type="continuous">
  <origin xyz="0.0106 0.005 -0.0348" rpy="0 0 0"/>
  <parent link="BR_shoulder_servo1"/>
  <child link="BR_shoulder_servo_arm1"/>
  <axis xyz="1.0 0.0 -0.0"/>
</joint>
<transmission name="Revolute_45_tran">
  <type>transmission_interface/SimpleTransmission</type>
  <joint name="Revolute_45">
    <hardwareInterface>PositionJointInterface</hardwareInterface>
  </joint>
  <actuator name="Revolute_45_actr">
    <hardwareInterface>PositionJointInterface</hardwareInterface>
    <mechanicalReduction>1</mechanicalReduction>
  </actuator>
</transmission>

<joint name="Rigid_46" type="fixed">
  <origin xyz="0.006 0.0 0.0" rpy="0 0 0"/>
  <parent link="BR_shoulder_servo_arm1"/>
  <child link="BR_leg_hip_servo_holder1"/>
</joint>

<joint name="Rigid_48" type="fixed">
  <origin xyz="-0.245915 0.24861 -0.296444" rpy="0 0 0"/>
  <parent link="BR_leg_ankle2"/>
  <child link="BR_leg_foot2Component161"/>
</joint>

<joint name="Revolute_49" type="continuous">
  <origin xyz="0.251734 -0.242196 0.183261" rpy="0 0 0"/>
  <parent link="BR_leg_knee_up2"/>
  <child link="BR_leg_ankle2"/>
  <axis xyz="0.0 -1.0 -0.0"/>
</joint>
<transmission name="Revolute_49_tran">
  <type>transmission_interface/SimpleTransmission</type>
  <joint name="Revolute_49">
    <hardwareInterface>PositionJointInterface</hardwareInterface>
  </joint>
  <actuator name="Revolute_49_actr">
    <hardwareInterface>PositionJointInterface</hardwareInterface>
    <mechanicalReduction>1</mechanicalReduction>
  </actuator>
</transmission>

<joint name="Rigid_50" type="fixed">
  <origin xyz="0.0 0.006 0.0" rpy="0 0 0"/>
  <parent link="BR_femur_servo_arm2"/>
  <child link="BR_leg_knee_up2"/>
</joint>

<joint name="Revolute_51" type="continuous">
  <origin xyz="-0.103826 0.266096 0.331816" rpy="0 0 0"/>
  <parent link="BR_femur_servo2"/>
  <child link="BR_femur_servo_arm2"/>
  <axis xyz="0.0 -1.0 0.0"/>
</joint>
<transmission name="Revolute_51_tran">
  <type>transmission_interface/SimpleTransmission</type>
  <joint name="Revolute_51">
    <hardwareInterface>PositionJointInterface</hardwareInterface>
  </joint>
  <actuator name="Revolute_51_actr">
    <hardwareInterface>PositionJointInterface</hardwareInterface>
    <mechanicalReduction>1</mechanicalReduction>
  </actuator>
</transmission>

<joint name="Rigid_52" type="fixed">
  <origin xyz="-0.032801 -0.247296 -0.312895" rpy="0 0 0"/>
  <parent link="BR_leg_hip_servo_holder1"/>
  <child link="BR_femur_servo2"/>
</joint>

<joint name="Rigid_53" type="fixed">
  <origin xyz="-0.032801 -0.247296 -0.292395" rpy="0 0 0"/>
  <parent link="BR_leg_hip_servo_holder1"/>
  <child link="BR_tibia_servo2"/>
</joint>

<joint name="Rigid_54" type="fixed">
  <origin xyz="-0.1314 0.206596 0.185195" rpy="0 0 0"/>
  <parent link="base_link"/>
  <child link="FR_shoulder_servo1"/>
</joint>

<joint name="Rigid_55" type="fixed">
  <origin xyz="-0.051146 0.206596 0.185195" rpy="0 0 0"/>
  <parent link="base_link"/>
  <child link="BR_shoulder_servo1"/>
</joint>

<joint name="Rigid_56" type="fixed">
  <origin xyz="-0.067875 -0.0066 -0.059031" rpy="0 0 0"/>
  <parent link="BL_leg_ankle1"/>
  <child link="BL_leg_foot1Component491"/>
</joint>

<joint name="Revolute_57" type="continuous">
  <origin xyz="0.073641 0.0 -0.054152" rpy="0 0 0"/>
  <parent link="BL_leg_knee_up1"/>
  <child link="BL_leg_ankle1"/>
  <axis xyz="0.0 -1.0 -0.0"/>
</joint>
<transmission name="Revolute_57_tran">
  <type>transmission_interface/SimpleTransmission</type>
  <joint name="Revolute_57">
    <hardwareInterface>PositionJointInterface</hardwareInterface>
  </joint>
  <actuator name="Revolute_57_actr">
    <hardwareInterface>PositionJointInterface</hardwareInterface>
    <mechanicalReduction>1</mechanicalReduction>
  </actuator>
</transmission>

<joint name="Rigid_58" type="fixed">
  <origin xyz="0.0 -0.006 0.0" rpy="0 0 0"/>
  <parent link="BL_tibia_servo1"/>
  <child link="BL_leg_knee_up1"/>
</joint>

<joint name="Revolute_59" type="continuous">
  <origin xyz="0.0348 -0.0106 -0.005" rpy="0 0 0"/>
  <parent link="BL_femur_servo1"/>
  <child link="BL_tibia_servo1"/>
  <axis xyz="0.0 -1.0 -0.0"/>
</joint>
<transmission name="Revolute_59_tran">
  <type>transmission_interface/SimpleTransmission</type>
  <joint name="Revolute_59">
    <hardwareInterface>PositionJointInterface</hardwareInterface>
  </joint>
  <actuator name="Revolute_59_actr">
    <hardwareInterface>PositionJointInterface</hardwareInterface>
    <mechanicalReduction>1</mechanicalReduction>
  </actuator>
</transmission>

<joint name="Rigid_60" type="fixed">
  <origin xyz="-0.057373 -0.0102 0.023921" rpy="0 0 0"/>
  <parent link="FL_leg_hip_servo_holder1"/>
  <child link="BL_femur_servo1"/>
</joint>

<joint name="Rigid_61" type="fixed">
  <origin xyz="-0.057373 -0.0102 0.003421" rpy="0 0 0"/>
  <parent link="FL_leg_hip_servo_holder1"/>
  <child link="FL_tibia_servo1"/>
</joint>

<joint name="Rigid_62" type="fixed">
  <origin xyz="-0.006 0.0 0.0" rpy="0 0 0"/>
  <parent link="FL_shoulder_servo_arm1"/>
  <child link="FL_leg_hip_servo_holder1"/>
</joint>

<joint name="Revolute_63" type="continuous">
  <origin xyz="-0.0106 -0.005 -0.0348" rpy="0 0 0"/>
  <parent link="FL_shoulder_servo1"/>
  <child link="FL_shoulder_servo_arm1"/>
  <axis xyz="-1.0 -0.0 -0.0"/>
</joint>
<transmission name="Revolute_63_tran">
  <type>transmission_interface/SimpleTransmission</type>
  <joint name="Revolute_63">
    <hardwareInterface>PositionJointInterface</hardwareInterface>
  </joint>
  <actuator name="Revolute_63_actr">
    <hardwareInterface>PositionJointInterface</hardwareInterface>
    <mechanicalReduction>1</mechanicalReduction>
  </actuator>
</transmission>

<joint name="Rigid_64" type="fixed">
  <origin xyz="-0.1314 0.113596 0.185195" rpy="0 0 0"/>
  <parent link="base_link"/>
  <child link="FL_shoulder_servo1"/>
</joint>

<joint name="Rigid_65" type="fixed">
  <origin xyz="0.384563 0.082883 -0.115649" rpy="0 0 0"/>
  <parent link="BL_leg_ankle2"/>
  <child link="BL_leg_foot2Component491"/>
</joint>

<joint name="Revolute_66" type="continuous">
  <origin xyz="0.073641 0.0 -0.054152" rpy="0 0 0"/>
  <parent link="BL_leg_knee_up2"/>
  <child link="BL_leg_ankle2"/>
  <axis xyz="-0.0 -1.0 0.0"/>
</joint>
<transmission name="Revolute_66_tran">
  <type>transmission_interface/SimpleTransmission</type>
  <joint name="Revolute_66">
    <hardwareInterface>PositionJointInterface</hardwareInterface>
  </joint>
  <actuator name="Revolute_66_actr">
    <hardwareInterface>PositionJointInterface</hardwareInterface>
    <mechanicalReduction>1</mechanicalReduction>
  </actuator>
</transmission>

<joint name="Rigid_67" type="fixed">
  <origin xyz="0.0 -0.006 0.0" rpy="0 0 0"/>
  <parent link="BL_tibia_servo2"/>
  <child link="BL_leg_knee_up2"/>
</joint>

<joint name="Revolute_68" type="continuous">
  <origin xyz="-0.103226 -0.144696 -0.016754" rpy="0 0 0"/>
  <parent link="BL_femur_servo2"/>
  <child link="BL_tibia_servo2"/>
  <axis xyz="-0.0 -1.0 0.0"/>
</joint>
<transmission name="Revolute_68_tran">
  <type>transmission_interface/SimpleTransmission</type>
  <joint name="Revolute_68">
    <hardwareInterface>PositionJointInterface</hardwareInterface>
  </joint>
  <actuator name="Revolute_68_actr">
    <hardwareInterface>PositionJointInterface</hardwareInterface>
    <mechanicalReduction>1</mechanicalReduction>
  </actuator>
</transmission>

<joint name="Rigid_69" type="fixed">
  <origin xyz="-0.032801 0.123896 0.035706" rpy="0 0 0"/>
  <parent link="BL_leg_hip_servo_holder1"/>
  <child link="BL_femur_servo2"/>
</joint>

<joint name="Rigid_70" type="fixed">
  <origin xyz="-0.032801 0.123896 0.015206" rpy="0 0 0"/>
  <parent link="BL_leg_hip_servo_holder1"/>
  <child link="FL_tibia_servo2"/>
</joint>

<joint name="Rigid_71" type="fixed">
  <origin xyz="0.006 0.0 0.0" rpy="0 0 0"/>
  <parent link="BL_shoulder_servo_arm1"/>
  <child link="BL_leg_hip_servo_holder1"/>
</joint>

<joint name="Revolute_72" type="continuous">
  <origin xyz="0.0106 -0.005 -0.0348" rpy="0 0 0"/>
  <parent link="BL_shoulder_servo1"/>
  <child link="BL_shoulder_servo_arm1"/>
  <axis xyz="-1.0 -0.0 -0.0"/>
</joint>
<transmission name="Revolute_72_tran">
  <type>transmission_interface/SimpleTransmission</type>
  <joint name="Revolute_72">
    <hardwareInterface>PositionJointInterface</hardwareInterface>
  </joint>
  <actuator name="Revolute_72_actr">
    <hardwareInterface>PositionJointInterface</hardwareInterface>
    <mechanicalReduction>1</mechanicalReduction>
  </actuator>
</transmission>

<joint name="Rigid_73" type="fixed">
  <origin xyz="-0.051146 0.113596 0.185164" rpy="0 0 0"/>
  <parent link="base_link"/>
  <child link="BL_shoulder_servo1"/>
</joint>

</robot>
